Workbook
Name 室内光缆: RD!$A$2:$A$13
Name 室外光缆: RD!$A$14:$A$22
Name 网线: RD!$A$27:$A$40
Name 电话线: RD!$A$41:$A$44
Name 大对数电缆: RD!$A$23:$A$26
Name RVV信号线: RD!$A$45:$A$61
Name RVVP信号线: RD!$A$67:$A$86
Name RVS信号线: RD!$A$62:$A$66
Name RVSP信号线: RD!$A$87:$A$91
Name 话筒线: RD!$A$92:$A$97
Name 音响线: RD!$A$98:$A$104
Name 同轴线缆: RD!$A$105:$A$111
Name 电梯随行电缆: RD!$A$112:$A$113
Name RVV电源线: QD!$A$2:$A$7
Name BV电源线: QD!$A$8:$A$11
Name BVR电源线: QD!$A$12:$A$15
Name YJV3芯电源线: QD!$A$16:$A$22
Name YJV5芯电源线: QD!$A$23:$A$44
Name RDWJ: RD!$B$2:$B$138
Name RDJMJ: RD!$C$2:$C$138
Name RDGS: RD!$D$2:$D$138
Name QDGS: QD!$D$2:$D$57
Name QDWJ: QD!$B$2:$B$57
Name QDJMJ: QD!$C$2:$C$57
Name RDDXWJ: RD!$B$7:$B$26
Name RDDXGS: RD!$D$7:$D$26

Sheet 线管桥架计算
B1: 常用线缆穿管、桥架计算
B2: 《民用建筑电气设计标准》GB 51348-2019 | C2: 弱电线管 | D2: 26.5.7 1 单根25对及以上的大对数对绞电缆、12芯及以上光缆或单根其他弱电主干线缆，当在1根直线导管内敷设时，其管径利用率不宜大于50%；当在1根弯曲段导管内敷设时，其管径利用率不宜大于40%。 | N2: 0.4 | Q2: 选择管材类型 | R2: 套接紧定式钢管（JDG）
D3: 26.5.7 2 同一根导管内敷设多根4对对绞电缆或多根4芯及以下配线光缆或多根其他弱电线缆时，其管径截面积利用率不应大于30%。 | N3: 0.3 | Q3: 弱电线缆
C4: 弱电桥架 | D4: 26.5.7 3 同一根槽盒内可同时敷设多根电缆或光缆，其电缆槽盒截面积利用率不应大于50%。 | N4: 0.5 | Q4: 线缆总根数 | R4: =SUM(RDGS) -> 1 | V4: 线缆总截面积 | W4: =SUMPRODUCT(RDJMJ,RDGS) -> 18.095574
Q5: 建议管径 | R5: {=_xlfn.IFS(R4=0,"-",AND(R4=1,SUM(RDDXGS)=1),_xlfn.IFS($R$2="低压流体输送用焊接钢管（SC）",_xlfn.XLOOKUP(_xlfn.XLOOKUP(1,RDDXGS,RDDXWJ,0,0,1)/$N$2,基础数据!$N$4:$N$15,基础数据!$K$4:$K$15,"建议桥架敷设",1,1),$R$2="套接紧定式钢管（JDG）",_xlfn.XLOOKUP(_xlfn.XLOOKUP(1,RDDXGS,RDDXWJ,0,0,1)/$N$2,基础数据!$N$16:$N$21,基础数据!$K$16:$K$21,"建议桥架敷设",1,1),$R$2="聚氯乙烯硬质电线管（PC）",_xlfn.XLOOKUP(_xlfn.XLOOKUP(1,RDDXGS,RDDXWJ,0,0,1)/$N$2,基础数据!$N$22:$N$27,基础数据!$K$22:$K$27,"建议桥架敷设",1,1),$R$2="聚氯乙烯半硬质电线管（FPC）",_xlfn.XLOOKUP(_xlfn.XLOOKUP(1,RDDXGS,RDDXWJ,0,0,1)/$N$2,基础数据!$N$28:$N$33,基础数据!$K$28:$K$33,"建议桥架敷设",1,1),$R$2="聚氯乙烯（PVC-U）",_xlfn.XLOOKUP(_xlfn.XLOOKUP(1,RDDXGS,RDDXWJ,0,0,1)/$N$2,基础数据!$N$37:$N$46,基础数据!$K$37:$K$46,"建议桥架敷设",1,1),$R$2="聚乙烯（PE）",_xlfn.XLOOKUP(_xlfn.XLOOKUP(1,RDDXGS,RDDXWJ,0,0,1)/$N$2,基础数据!$N$51:$N$62,基础数据!$K$51:$K$62,"建议桥架敷设",1,1),$R$2="双壁波纹管",_xlfn.XLOOKUP(_xlfn.XLOOKUP(1,RDDXGS,RDDXWJ,0,0,1)/$N$2,基础数据!$N$67:$N$72,基础数据!$K$67:$K$72,"建议桥架敷设",1,1),$R$2="套接扣压式薄壁钢导管（KBG）",_xlfn.XLOOKUP(_xlfn.XLOOKUP(1,RDDXGS,RDDXWJ,0,0,1)/$N$2,基础数据!$N$106:$N$110,基础数据!$K$106:$K$110,"建议桥架敷设",1,1)),$R$2="低压流体输送用焊接钢管（SC）",_xlfn.XLOOKUP(W4/$N$3,基础数据!$O$4:$O$15,基础数据!$K$4:$K$15,"建议桥架敷设",1,1),$R$2="套接紧定式钢管（JDG）",_xlfn.XLOOKUP(W4/$N$3,基础数据!$O$16:$O$21,基础数据!$K$16:$K$21,"建议桥架敷设",1,1),$R$2="聚氯乙烯硬质电线管（PC）",_xlfn.XLOOKUP(W4/$N$3,基础数据!$O$22:$O$27,基础数据!$K$22:$K$27,"建议桥架敷设",1,1),$R$2="聚氯乙烯半硬质电线管（FPC）",_xlfn.XLOOKUP(W4/$N$3,基础数据!$O$28:$O$33,基础数据!$K$28:$K$33,"建议桥架敷设",1,1),$R$2="聚氯乙烯（PVC-U）",_xlfn.XLOOKUP(W4/$N$3,基础数据!$O$37:$O$46,基础数据!$K$37:$K$46,"建议桥架敷设",1,1),$R$2="聚乙烯（PE）",_xlfn.XLOOKUP(W4/$N$3,基础数据!$O$51:$O$62,基础数据!$K$51:$K$62,"建议桥架敷设",1,1),$R$2="双壁波纹管",_xlfn.XLOOKUP(W4/$N$3,基础数据!$O$67:$O$72,基础数据!$K$67:$K$72,"建议桥架敷设",1,1),$R$2="套接扣压式薄壁钢导管（KBG）",_xlfn.XLOOKUP(W4/$N$3,基础数据!$O$106:$O$110,基础数据!$K$106:$K$110,"建议桥架敷设",1,1))} -> Φ16 | V5: 线管截面积 | W5: =_xlfn.IFS($R$2="低压流体输送用焊接钢管（SC）",_xlfn.XLOOKUP(R5,基础数据!$K$4:$K$15,基础数据!$O$4:$O$15,"-",0,1),$R$2="套接紧定式钢管（JDG）",_xlfn.XLOOKUP(R5,基础数据!$K$16:$K$21,基础数据!$O$16:$O$21,"-",0,1),$R$2="聚氯乙烯硬质电线管（PC）",_xlfn.XLOOKUP(R5,基础数据!$K$22:$K$27,基础数据!$O$22:$O$27,"-",0,1),$R$2="聚氯乙烯半硬质电线管（FPC）",_xlfn.XLOOKUP(R5,基础数据!$K$28:$K$33,基础数据!$O$28:$O$33,"-",0,1),$R$2="聚氯乙烯（PVC-U）",_xlfn.XLOOKUP(R5,基础数据!$K$37:$K$46,基础数据!$O$37:$O$46,"-",0,1),$R$2="聚乙烯（PE）",_xlfn.XLOOKUP(R5,基础数据!$K$51:$K$62,基础数据!$O$51:$O$62,"-",0,1),$R$2="双壁波纹管",_xlfn.XLOOKUP(R5,基础数据!$K$67:$K$72,基础数据!$O$67:$O$72,"-",0,1),$R$2="套接扣压式薄壁钢导管（KBG）",_xlfn.XLOOKUP(R5,基础数据!$K$106:$K$110,基础数据!$O$106:$O$110,"-",0,1)) -> 132
Q6: 建议桥架规格 | R6: =IF(W4=0,"-",_xlfn.XLOOKUP(W4/$N$4,基础数据!$X$4:$X$26,基础数据!$U$4:$U$26,"线缆过多，请手动选择桥架",1,1)) -> 50*50 | V6: 桥架截面积 | W6: =_xlfn.XLOOKUP(R6,基础数据!$U$4:$U$26,基础数据!$X$4:$X$26,"-",0,1) -> 2500
B8: 光缆 | C8: 外径 | D8: 截面积 | E8: 根数 | F8: 建议管径 | G8: 铜缆 | H8: 外径 | I8: 截面积 | J8: 根数 | K8: 建议管径 | L8: 信号线 | M8: 外径 | N8: 截面积 | O8: 根数 | P8: 建议管径 | Q8: 信号线 | R8: 外径 | S8: 截面积 | T8: 根数 | U8: 建议管径 | V8: 话筒线 | W8: 外径 | X8: 截面积 | Y8: 根数 | Z8: 建议管径
B9: 2芯皮线光缆 | C9: 3 | D9: =天诚!D30 -> 6 | F9: =_xlfn.IFS(E9=0,"-",$R$2="低压流体输送用焊接钢管（SC）",_xlfn.XLOOKUP(D9*E9/$N$3,基础数据!$O$4:$O$15,基础数据!$K$4:$K$15,"建议桥架敷设",1,1),$R$2="套接紧定式钢管（JDG）",_xlfn.XLOOKUP(D9*E9/$N$3,基础数据!$O$16:$O$21,基础数据!$K$16:$K$21,"建议桥架敷设",1,1),$R$2="聚氯乙烯硬质电线管（PC）",_xlfn.XLOOKUP(D9*E9/$N$3,基础数据!$O$22:$O$27,基础数据!$K$22:$K$27,"建议桥架敷设",1,1),$R$2="聚氯乙烯半硬质电线管（FPC）",_xlfn.XLOOKUP(D9*E9/$N$3,基础数据!$O$28:$O$33,基础数据!$K$28:$K$33,"建议桥架敷设",1,1),$R$2="聚氯乙烯（PVC-U）",_xlfn.XLOOKUP(D9*E9/$N$3,基础数据!$O$37:$O$46,基础数据!$K$37:$K$46,"建议桥架敷设",1,1),$R$2="聚乙烯（PE）",_xlfn.XLOOKUP(D9*E9/$N$3,基础数据!$O$51:$O$62,基础数据!$K$51:$K$62,"建议桥架敷设",1,1),$R$2="双壁波纹管",_xlfn.XLOOKUP(D9*E9/$N$3,基础数据!$O$67:$O$72,基础数据!$K$67:$K$72,"建议桥架敷设",1,1),$R$2="套接扣压式薄壁钢导管（KBG）",_xlfn.XLOOKUP(D9*E9/$N$3,基础数据!$O$106:$O$110,基础数据!$K$106:$K$110,"建议桥架敷设",1,1)) -> - | G9: =天诚!B4 -> UTP-CAT.5E | H9: =天诚!C4 -> 5.3 | I9: =(H9/2)^2*PI() -> 22.061834 | K9: =_xlfn.IFS(J9=0,"-",$R$2="低压流体输送用焊接钢管（SC）",_xlfn.XLOOKUP(I9*J9/$N$3,基础数据!$O$4:$O$15,基础数据!$K$4:$K$15,"建议桥架敷设",1,1),$R$2="套接紧定式钢管（JDG）",_xlfn.XLOOKUP(I9*J9/$N$3,基础数据!$O$16:$O$21,基础数据!$K$16:$K$21,"建议桥架敷设",1,1),$R$2="聚氯乙烯硬质电线管（PC）",_xlfn.XLOOKUP(I9*J9/$N$3,基础数据!$O$22:$O$27,基础数据!$K$22:$K$27,"建议桥架敷设",1,1),$R$2="聚氯乙烯半硬质电线管（FPC）",_xlfn.XLOOKUP(I9*J9/$N$3,基础数据!$O$28:$O$33,基础数据!$K$28:$K$33,"建议桥架敷设",1,1),$R$2="聚氯乙烯（PVC-U）",_xlfn.XLOOKUP(I9*J9/$N$3,基础数据!$O$37:$O$46,基础数据!$K$37:$K$46,"建议桥架敷设",1,1),$R$2="聚乙烯（PE）",_xlfn.XLOOKUP(I9*J9/$N$3,基础数据!$O$51:$O$62,基础数据!$K$51:$K$62,"建议桥架敷设",1,1),$R$2="双壁波纹管",_xlfn.XLOOKUP(I9*J9/$N$3,基础数据!$O$67:$O$72,基础数据!$K$67:$K$72,"建议桥架敷设",1,1),$R$2="套接扣压式薄壁钢导管（KBG）",_xlfn.XLOOKUP(I9*J9/$N$3,基础数据!$O$106:$O$110,基础数据!$K$106:$K$110,"建议桥架敷设",1,1)) -> - | L9: =飞鹤!A14 -> RVV-2*0.5 | M9: =飞鹤!B14 -> 5.9 | N9: =(M9/2)^2*PI() -> 27.33971 | P9: =_xlfn.IFS(O9=0,"-",$R$2="低压流体输送用焊接钢管（SC）",_xlfn.XLOOKUP(N9*O9/$N$3,基础数据!$O$4:$O$15,基础数据!$K$4:$K$15,"建议桥架敷设",1,1),$R$2="套接紧定式钢管（JDG）",_xlfn.XLOOKUP(N9*O9/$N$3,基础数据!$O$16:$O$21,基础数据!$K$16:$K$21,"建议桥架敷设",1,1),$R$2="聚氯乙烯硬质电线管（PC）",_xlfn.XLOOKUP(N9*O9/$N$3,基础数据!$O$22:$O$27,基础数据!$K$22:$K$27,"建议桥架敷设",1,1),$R$2="聚氯乙烯半硬质电线管（FPC）",_xlfn.XLOOKUP(N9*O9/$N$3,基础数据!$O$28:$O$33,基础数据!$K$28:$K$33,"建议桥架敷设",1,1),$R$2="聚氯乙烯（PVC-U）",_xlfn.XLOOKUP(N9*O9/$N$3,基础数据!$O$37:$O$46,基础数据!$K$37:$K$46,"建议桥架敷设",1,1),$R$2="聚乙烯（PE）",_xlfn.XLOOKUP(N9*O9/$N$3,基础数据!$O$51:$O$62,基础数据!$K$51:$K$62,"建议桥架敷设",1,1),$R$2="双壁波纹管",_xlfn.XLOOKUP(N9*O9/$N$3,基础数据!$O$67:$O$72,基础数据!$K$67:$K$72,"建议桥架敷设",1,1),$R$2="套接扣压式薄壁钢导管（KBG）",_xlfn.XLOOKUP(N9*O9/$N$3,基础数据!$O$106:$O$110,基础数据!$K$106:$K$110,"建议桥架敷设",1,1)) -> - | Q9: =飞鹤!A86 -> RVVP-2*0.5 | R9: =飞鹤!B86 -> 6.8 | S9: =(R9/2)^2*PI() -> 36.316811 | U9: =_xlfn.IFS(T9=0,"-",$R$2="低压流体输送用焊接钢管（SC）",_xlfn.XLOOKUP(S9*T9/$N$3,基础数据!$O$4:$O$15,基础数据!$K$4:$K$15,"建议桥架敷设",1,1),$R$2="套接紧定式钢管（JDG）",_xlfn.XLOOKUP(S9*T9/$N$3,基础数据!$O$16:$O$21,基础数据!$K$16:$K$21,"建议桥架敷设",1,1),$R$2="聚氯乙烯硬质电线管（PC）",_xlfn.XLOOKUP(S9*T9/$N$3,基础数据!$O$22:$O$27,基础数据!$K$22:$K$27,"建议桥架敷设",1,1),$R$2="聚氯乙烯半硬质电线管（FPC）",_xlfn.XLOOKUP(S9*T9/$N$3,基础数据!$O$28:$O$33,基础数据!$K$28:$K$33,"建议桥架敷设",1,1),$R$2="聚氯乙烯（PVC-U）",_xlfn.XLOOKUP(S9*T9/$N$3,基础数据!$O$37:$O$46,基础数据!$K$37:$K$46,"建议桥架敷设",1,1),$R$2="聚乙烯（PE）",_xlfn.XLOOKUP(S9*T9/$N$3,基础数据!$O$51:$O$62,基础数据!$K$51:$K$62,"建议桥架敷设",1,1),$R$2="双壁波纹管",_xlfn.XLOOKUP(S9*T9/$N$3,基础数据!$O$67:$O$72,基础数据!$K$67:$K$72,"建议桥架敷设",1,1),$R$2="套接扣压式薄壁钢导管（KBG）",_xlfn.XLOOKUP(S9*T9/$N$3,基础数据!$O$106:$O$110,基础数据!$K$106:$K$110,"建议桥架敷设",1,1)) -> - | V9: =天诚!B65 -> HTP-2*20/0.10 | W9: =天诚!C65 -> 6 | X9: =(W9/2)^2*PI() -> 28.274334 | Z9: =_xlfn.IFS(Y9=0,"-",$R$2="低压流体输送用焊接钢管（SC）",_xlfn.XLOOKUP(X9*Y9/$N$3,基础数据!$O$4:$O$15,基础数据!$K$4:$K$15,"建议桥架敷设",1,1),$R$2="套接紧定式钢管（JDG）",_xlfn.XLOOKUP(X9*Y9/$N$3,基础数据!$O$16:$O$21,基础数据!$K$16:$K$21,"建议桥架敷设",1,1),$R$2="聚氯乙烯硬质电线管（PC）",_xlfn.XLOOKUP(X9*Y9/$N$3,基础数据!$O$22:$O$27,基础数据!$K$22:$K$27,"建议桥架敷设",1,1),$R$2="聚氯乙烯半硬质电线管（FPC）",_xlfn.XLOOKUP(X9*Y9/$N$3,基础数据!$O$28:$O$33,基础数据!$K$28:$K$33,"建议桥架敷设",1,1),$R$2="聚氯乙烯（PVC-U）",_xlfn.XLOOKUP(X9*Y9/$N$3,基础数据!$O$37:$O$46,基础数据!$K$37:$K$46,"建议桥架敷设",1,1),$R$2="聚乙烯（PE）",_xlfn.XLOOKUP(X9*Y9/$N$3,基础数据!$O$51:$O$62,基础数据!$K$51:$K$62,"建议桥架敷设",1,1),$R$2="双壁波纹管",_xlfn.XLOOKUP(X9*Y9/$N$3,基础数据!$O$67:$O$72,基础数据!$K$67:$K$72,"建议桥架敷设",1,1),$R$2="套接扣压式薄壁钢导管（KBG）",_xlfn.XLOOKUP(X9*Y9/$N$3,基础数据!$O$106:$O$110,基础数据!$K$106:$K$110,"建议桥架敷设",1,1)) -> -
B10: =长飞!A3 -> 2芯室内光缆 | C10: =长飞!B3 -> 4 | D10: =(C10/2)^2*PI() -> 12.566371 | F10: =_xlfn.IFS(E10=0,"-",$R$2="低压流体输送用焊接钢管（SC）",_xlfn.XLOOKUP(D10*E10/$N$3,基础数据!$O$4:$O$15,基础数据!$K$4:$K$15,"建议桥架敷设",1,1),$R$2="套接紧定式钢管（JDG）",_xlfn.XLOOKUP(D10*E10/$N$3,基础数据!$O$16:$O$21,基础数据!$K$16:$K$21,"建议桥架敷设",1,1),$R$2="聚氯乙烯硬质电线管（PC）",_xlfn.XLOOKUP(D10*E10/$N$3,基础数据!$O$22:$O$27,基础数据!$K$22:$K$27,"建议桥架敷设",1,1),$R$2="聚氯乙烯半硬质电线管（FPC）",_xlfn.XLOOKUP(D10*E10/$N$3,基础数据!$O$28:$O$33,基础数据!$K$28:$K$33,"建议桥架敷设",1,1),$R$2="聚氯乙烯（PVC-U）",_xlfn.XLOOKUP(D10*E10/$N$3,基础数据!$O$37:$O$46,基础数据!$K$37:$K$46,"建议桥架敷设",1,1),$R$2="聚乙烯（PE）",_xlfn.XLOOKUP(D10*E10/$N$3,基础数据!$O$51:$O$62,基础数据!$K$51:$K$62,"建议桥架敷设",1,1),$R$2="双壁波纹管",_xlfn.XLOOKUP(D10*E10/$N$3,基础数据!$O$67:$O$72,基础数据!$K$67:$K$72,"建议桥架敷设",1,1),$R$2="套接扣压式薄壁钢导管（KBG）",_xlfn.XLOOKUP(D10*E10/$N$3,基础数据!$O$106:$O$110,基础数据!$K$106:$K$110,"建议桥架敷设",1,1)) -> - | G10: =天诚!B5 -> FTP-CAT.5E | H10: =天诚!C5 -> 6.5 | I10: =(H10/2)^2*PI() -> 33.183072 | K10: =_xlfn.IFS(J10=0,"-",$R$2="低压流体输送用焊接钢管（SC）",_xlfn.XLOOKUP(I10*J10/$N$3,基础数据!$O$4:$O$15,基础数据!$K$4:$K$15,"建议桥架敷设",1,1),$R$2="套接紧定式钢管（JDG）",_xlfn.XLOOKUP(I10*J10/$N$3,基础数据!$O$16:$O$21,基础数据!$K$16:$K$21,"建议桥架敷设",1,1),$R$2="聚氯乙烯硬质电线管（PC）",_xlfn.XLOOKUP(I10*J10/$N$3,基础数据!$O$22:$O$27,基础数据!$K$22:$K$27,"建议桥架敷设",1,1),$R$2="聚氯乙烯半硬质电线管（FPC）",_xlfn.XLOOKUP(I10*J10/$N$3,基础数据!$O$28:$O$33,基础数据!$K$28:$K$33,"建议桥架敷设",1,1),$R$2="聚氯乙烯（PVC-U）",_xlfn.XLOOKUP(I10*J10/$N$3,基础数据!$O$37:$O$46,基础数据!$K$37:$K$46,"建议桥架敷设",1,1),$R$2="聚乙烯（PE）",_xlfn.XLOOKUP(I10*J10/$N$3,基础数据!$O$51:$O$62,基础数据!$K$51:$K$62,"建议桥架敷设",1,1),$R$2="双壁波纹管",_xlfn.XLOOKUP(I10*J10/$N$3,基础数据!$O$67:$O$72,基础数据!$K$67:$K$72,"建议桥架敷设",1,1),$R$2="套接扣压式薄壁钢导管（KBG）",_xlfn.XLOOKUP(I10*J10/$N$3,基础数据!$O$106:$O$110,基础数据!$K$106:$K$110,"建议桥架敷设",1,1)) -> - | L10: =飞鹤!A15 -> RVV-2*0.75 | M10: =飞鹤!B15 -> 6.3 | N10: =(M10/2)^2*PI() -> 31.172453 | P10: =_xlfn.IFS(O10=0,"-",$R$2="低压流体输送用焊接钢管（SC）",_xlfn.XLOOKUP(N10*O10/$N$3,基础数据!$O$4:$O$15,基础数据!$K$4:$K$15,"建议桥架敷设",1,1),$R$2="套接紧定式钢管（JDG）",_xlfn.XLOOKUP(N10*O10/$N$3,基础数据!$O$16:$O$21,基础数据!$K$16:$K$21,"建议桥架敷设",1,1),$R$2="聚氯乙烯硬质电线管（PC）",_xlfn.XLOOKUP(N10*O10/$N$3,基础数据!$O$22:$O$27,基础数据!$K$22:$K$27,"建议桥架敷设",1,1),$R$2="聚氯乙烯半硬质电线管（FPC）",_xlfn.XLOOKUP(N10*O10/$N$3,基础数据!$O$28:$O$33,基础数据!$K$28:$K$33,"建议桥架敷设",1,1),$R$2="聚氯乙烯（PVC-U）",_xlfn.XLOOKUP(N10*O10/$N$3,基础数据!$O$37:$O$46,基础数据!$K$37:$K$46,"建议桥架敷设",1,1),$R$2="聚乙烯（PE）",_xlfn.XLOOKUP(N10*O10/$N$3,基础数据!$O$51:$O$62,基础数据!$K$51:$K$62,"建议桥架敷设",1,1),$R$2="双壁波纹管",_xlfn.XLOOKUP(N10*O10/$N$3,基础数据!$O$67:$O$72,基础数据!$K$67:$K$72,"建议桥架敷设",1,1),$R$2="套接扣压式薄壁钢导管（KBG）",_xlfn.XLOOKUP(N10*O10/$N$3,基础数据!$O$106:$O$110,基础数据!$K$106:$K$110,"建议桥架敷设",1,1)) -> - | Q10: =飞鹤!A87 -> RVVP-2*0.75 | R10: =飞鹤!B87 -> 7.4 | S10: =(R10/2)^2*PI() -> 43.008403 | U10: =_xlfn.IFS(T10=0,"-",$R$2="低压流体输送用焊接钢管（SC）",_xlfn.XLOOKUP(S10*T10/$N$3,基础数据!$O$4:$O$15,基础数据!$K$4:$K$15,"建议桥架敷设",1,1),$R$2="套接紧定式钢管（JDG）",_xlfn.XLOOKUP(S10*T10/$N$3,基础数据!$O$16:$O$21,基础数据!$K$16:$K$21,"建议桥架敷设",1,1),$R$2="聚氯乙烯硬质电线管（PC）",_xlfn.XLOOKUP(S10*T10/$N$3,基础数据!$O$22:$O$27,基础数据!$K$22:$K$27,"建议桥架敷设",1,1),$R$2="聚氯乙烯半硬质电线管（FPC）",_xlfn.XLOOKUP(S10*T10/$N$3,基础数据!$O$28:$O$33,基础数据!$K$28:$K$33,"建议桥架敷设",1,1),$R$2="聚氯乙烯（PVC-U）",_xlfn.XLOOKUP(S10*T10/$N$3,基础数据!$O$37:$O$46,基础数据!$K$37:$K$46,"建议桥架敷设",1,1),$R$2="聚乙烯（PE）",_xlfn.XLOOKUP(S10*T10/$N$3,基础数据!$O$51:$O$62,基础数据!$K$51:$K$62,"建议桥架敷设",1,1),$R$2="双壁波纹管",_xlfn.XLOOKUP(S10*T10/$N$3,基础数据!$O$67:$O$72,基础数据!$K$67:$K$72,"建议桥架敷设",1,1),$R$2="套接扣压式薄壁钢导管（KBG）",_xlfn.XLOOKUP(S10*T10/$N$3,基础数据!$O$106:$O$110,基础数据!$K$106:$K$110,"建议桥架敷设",1,1)) -> - | V10: =天诚!B66 -> HTP-2*27/0.10 | W10: =天诚!C66 -> 6 | X10: =(W10/2)^2*PI() -> 28.274334 | Z10: =_xlfn.IFS(Y10=0,"-",$R$2="低压流体输送用焊接钢管（SC）",_xlfn.XLOOKUP(X10*Y10/$N$3,基础数据!$O$4:$O$15,基础数据!$K$4:$K$15,"建议桥架敷设",1,1),$R$2="套接紧定式钢管（JDG）",_xlfn.XLOOKUP(X10*Y10/$N$3,基础数据!$O$16:$O$21,基础数据!$K$16:$K$21,"建议桥架敷设",1,1),$R$2="聚氯乙烯硬质电线管（PC）",_xlfn.XLOOKUP(X10*Y10/$N$3,基础数据!$O$22:$O$27,基础数据!$K$22:$K$27,"建议桥架敷设",1,1),$R$2="聚氯乙烯半硬质电线管（FPC）",_xlfn.XLOOKUP(X10*Y10/$N$3,基础数据!$O$28:$O$33,基础数据!$K$28:$K$33,"建议桥架敷设",1,1),$R$2="聚氯乙烯（PVC-U）",_xlfn.XLOOKUP(X10*Y10/$N$3,基础数据!$O$37:$O$46,基础数据!$K$37:$K$46,"建议桥架敷设",1,1),$R$2="聚乙烯（PE）",_xlfn.XLOOKUP(X10*Y10/$N$3,基础数据!$O$51:$O$62,基础数据!$K$51:$K$62,"建议桥架敷设",1,1),$R$2="双壁波纹管",_xlfn.XLOOKUP(X10*Y10/$N$3,基础数据!$O$67:$O$72,基础数据!$K$67:$K$72,"建议桥架敷设",1,1),$R$2="套接扣压式薄壁钢导管（KBG）",_xlfn.XLOOKUP(X10*Y10/$N$3,基础数据!$O$106:$O$110,基础数据!$K$106:$K$110,"建议桥架敷设",1,1)) -> -
B11: =长飞!A4 -> 4芯室内光缆 | C11: =长飞!B4 -> 4.8 | D11: =(C11/2)^2*PI() -> 18.095574 | E11: 1 | F11: =_xlfn.IFS(E11=0,"-",$R$2="低压流体输送用焊接钢管（SC）",_xlfn.XLOOKUP(D11*E11/$N$3,基础数据!$O$4:$O$15,基础数据!$K$4:$K$15,"建议桥架敷设",1,1),$R$2="套接紧定式钢管（JDG）",_xlfn.XLOOKUP(D11*E11/$N$3,基础数据!$O$16:$O$21,基础数据!$K$16:$K$21,"建议桥架敷设",1,1),$R$2="聚氯乙烯硬质电线管（PC）",_xlfn.XLOOKUP(D11*E11/$N$3,基础数据!$O$22:$O$27,基础数据!$K$22:$K$27,"建议桥架敷设",1,1),$R$2="聚氯乙烯半硬质电线管（FPC）",_xlfn.XLOOKUP(D11*E11/$N$3,基础数据!$O$28:$O$33,基础数据!$K$28:$K$33,"建议桥架敷设",1,1),$R$2="聚氯乙烯（PVC-U）",_xlfn.XLOOKUP(D11*E11/$N$3,基础数据!$O$37:$O$46,基础数据!$K$37:$K$46,"建议桥架敷设",1,1),$R$2="聚乙烯（PE）",_xlfn.XLOOKUP(D11*E11/$N$3,基础数据!$O$51:$O$62,基础数据!$K$51:$K$62,"建议桥架敷设",1,1),$R$2="双壁波纹管",_xlfn.XLOOKUP(D11*E11/$N$3,基础数据!$O$67:$O$72,基础数据!$K$67:$K$72,"建议桥架敷设",1,1),$R$2="套接扣压式薄壁钢导管（KBG）",_xlfn.XLOOKUP(D11*E11/$N$3,基础数据!$O$106:$O$110,基础数据!$K$106:$K$110,"建议桥架敷设",1,1)) -> #NAME? | G11: =天诚!B6 -> SFTP-CAT.5E | H11: =天诚!C6 -> 7 | I11: =(H11/2)^2*PI() -> 38.48451 | K11: =_xlfn.IFS(J11=0,"-",$R$2="低压流体输送用焊接钢管（SC）",_xlfn.XLOOKUP(I11*J11/$N$3,基础数据!$O$4:$O$15,基础数据!$K$4:$K$15,"建议桥架敷设",1,1),$R$2="套接紧定式钢管（JDG）",_xlfn.XLOOKUP(I11*J11/$N$3,基础数据!$O$16:$O$21,基础数据!$K$16:$K$21,"建议桥架敷设",1,1),$R$2="聚氯乙烯硬质电线管（PC）",_xlfn.XLOOKUP(I11*J11/$N$3,基础数据!$O$22:$O$27,基础数据!$K$22:$K$27,"建议桥架敷设",1,1),$R$2="聚氯乙烯半硬质电线管（FPC）",_xlfn.XLOOKUP(I11*J11/$N$3,基础数据!$O$28:$O$33,基础数据!$K$28:$K$33,"建议桥架敷设",1,1),$R$2="聚氯乙烯（PVC-U）",_xlfn.XLOOKUP(I11*J11/$N$3,基础数据!$O$37:$O$46,基础数据!$K$37:$K$46,"建议桥架敷设",1,1),$R$2="聚乙烯（PE）",_xlfn.XLOOKUP(I11*J11/$N$3,基础数据!$O$51:$O$62,基础数据!$K$51:$K$62,"建议桥架敷设",1,1),$R$2="双壁波纹管",_xlfn.XLOOKUP(I11*J11/$N$3,基础数据!$O$67:$O$72,基础数据!$K$67:$K$72,"建议桥架敷设",1,1),$R$2="套接扣压式薄壁钢导管（KBG）",_xlfn.XLOOKUP(I11*J11/$N$3,基础数据!$O$106:$O$110,基础数据!$K$106:$K$110,"建议桥架敷设",1,1)) -> - | L11: =飞鹤!A20 -> RVV-2*1.0 | M11: =飞鹤!B20 -> 7.5 | N11: =(M11/2)^2*PI() -> 44.178647 | P11: =_xlfn.IFS(O11=0,"-",$R$2="低压流体输送用焊接钢管（SC）",_xlfn.XLOOKUP(N11*O11/$N$3,基础数据!$O$4:$O$15,基础数据!$K$4:$K$15,"建议桥架敷设",1,1),$R$2="套接紧定式钢管（JDG）",_xlfn.XLOOKUP(N11*O11/$N$3,基础数据!$O$16:$O$21,基础数据!$K$16:$K$21,"建议桥架敷设",1,1),$R$2="聚氯乙烯硬质电线管（PC）",_xlfn.XLOOKUP(N11*O11/$N$3,基础数据!$O$22:$O$27,基础数据!$K$22:$K$27,"建议桥架敷设",1,1),$R$2="聚氯乙烯半硬质电线管（FPC）",_xlfn.XLOOKUP(N11*O11/$N$3,基础数据!$O$28:$O$33,基础数据!$K$28:$K$33,"建议桥架敷设",1,1),$R$2="聚氯乙烯（PVC-U）",_xlfn.XLOOKUP(N11*O11/$N$3,基础数据!$O$37:$O$46,基础数据!$K$37:$K$46,"建议桥架敷设",1,1),$R$2="聚乙烯（PE）",_xlfn.XLOOKUP(N11*O11/$N$3,基础数据!$O$51:$O$62,基础数据!$K$51:$K$62,"建议桥架敷设",1,1),$R$2="双壁波纹管",_xlfn.XLOOKUP(N11*O11/$N$3,基础数据!$O$67:$O$72,基础数据!$K$67:$K$72,"建议桥架敷设",1,1),$R$2="套接扣压式薄壁钢导管（KBG）",_xlfn.XLOOKUP(N11*O11/$N$3,基础数据!$O$106:$O$110,基础数据!$K$106:$K$110,"建议桥架敷设",1,1)) -> - | Q11: =飞鹤!A88 -> RVVP-2*1.0 | R11: =飞鹤!B88 -> 8.2 | S11: =(R11/2)^2*PI() -> 52.810173 | U11: =_xlfn.IFS(T11=0,"-",$R$2="低压流体输送用焊接钢管（SC）",_xlfn.XLOOKUP(S11*T11/$N$3,基础数据!$O$4:$O$15,基础数据!$K$4:$K$15,"建议桥架敷设",1,1),$R$2="套接紧定式钢管（JDG）",_xlfn.XLOOKUP(S11*T11/$N$3,基础数据!$O$16:$O$21,基础数据!$K$16:$K$21,"建议桥架敷设",1,1),$R$2="聚氯乙烯硬质电线管（PC）",_xlfn.XLOOKUP(S11*T11/$N$3,基础数据!$O$22:$O$27,基础数据!$K$22:$K$27,"建议桥架敷设",1,1),$R$2="聚氯乙烯半硬质电线管（FPC）",_xlfn.XLOOKUP(S11*T11/$N$3,基础数据!$O$28:$O$33,基础数据!$K$28:$K$33,"建议桥架敷设",1,1),$R$2="聚氯乙烯（PVC-U）",_xlfn.XLOOKUP(S11*T11/$N$3,基础数据!$O$37:$O$46,基础数据!$K$37:$K$46,"建议桥架敷设",1,1),$R$2="聚乙烯（PE）",_xlfn.XLOOKUP(S11*T11/$N$3,基础数据!$O$51:$O$62,基础数据!$K$51:$K$62,"建议桥架敷设",1,1),$R$2="双壁波纹管",_xlfn.XLOOKUP(S11*T11/$N$3,基础数据!$O$67:$O$72,基础数据!$K$67:$K$72,"建议桥架敷设",1,1),$R$2="套接扣压式薄壁钢导管（KBG）",_xlfn.XLOOKUP(S11*T11/$N$3,基础数据!$O$106:$O$110,基础数据!$K$106:$K$110,"建议桥架敷设",1,1)) -> - | V11: =天诚!B67 -> HTP-2*37/0.10 | W11: =天诚!C67 -> 6 | X11: =(W11/2)^2*PI() -> 28.274334 | Z11: =_xlfn.IFS(Y11=0,"-",$R$2="低压流体输送用焊接钢管（SC）",_xlfn.XLOOKUP(X11*Y11/$N$3,基础数据!$O$4:$O$15,基础数据!$K$4:$K$15,"建议桥架敷设",1,1),$R$2="套接紧定式钢管（JDG）",_xlfn.XLOOKUP(X11*Y11/$N$3,基础数据!$O$16:$O$21,基础数据!$K$16:$K$21,"建议桥架敷设",1,1),$R$2="聚氯乙烯硬质电线管（PC）",_xlfn.XLOOKUP(X11*Y11/$N$3,基础数据!$O$22:$O$27,基础数据!$K$22:$K$27,"建议桥架敷设",1,1),$R$2="聚氯乙烯半硬质电线管（FPC）",_xlfn.XLOOKUP(X11*Y11/$N$3,基础数据!$O$28:$O$33,基础数据!$K$28:$K$33,"建议桥架敷设",1,1),$R$2="聚氯乙烯（PVC-U）",_xlfn.XLOOKUP(X11*Y11/$N$3,基础数据!$O$37:$O$46,基础数据!$K$37:$K$46,"建议桥架敷设",1,1),$R$2="聚乙烯（PE）",_xlfn.XLOOKUP(X11*Y11/$N$3,基础数据!$O$51:$O$62,基础数据!$K$51:$K$62,"建议桥架敷设",1,1),$R$2="双壁波纹管",_xlfn.XLOOKUP(X11*Y11/$N$3,基础数据!$O$67:$O$72,基础数据!$K$67:$K$72,"建议桥架敷设",1,1),$R$2="套接扣压式薄壁钢导管（KBG）",_xlfn.XLOOKUP(X11*Y11/$N$3,基础数据!$O$106:$O$110,基础数据!$K$106:$K$110,"建议桥架敷设",1,1)) -> -
B12: =长飞!A5 -> 6芯室内光缆 | C12: =长飞!B5 -> 5.1 | D12: =(C12/2)^2*PI() -> 20.428206 | F12: =_xlfn.IFS(E12=0,"-",$R$2="低压流体输送用焊接钢管（SC）",_xlfn.XLOOKUP(D12*E12/$N$3,基础数据!$O$4:$O$15,基础数据!$K$4:$K$15,"建议桥架敷设",1,1),$R$2="套接紧定式钢管（JDG）",_xlfn.XLOOKUP(D12*E12/$N$3,基础数据!$O$16:$O$21,基础数据!$K$16:$K$21,"建议桥架敷设",1,1),$R$2="聚氯乙烯硬质电线管（PC）",_xlfn.XLOOKUP(D12*E12/$N$3,基础数据!$O$22:$O$27,基础数据!$K$22:$K$27,"建议桥架敷设",1,1),$R$2="聚氯乙烯半硬质电线管（FPC）",_xlfn.XLOOKUP(D12*E12/$N$3,基础数据!$O$28:$O$33,基础数据!$K$28:$K$33,"建议桥架敷设",1,1),$R$2="聚氯乙烯（PVC-U）",_xlfn.XLOOKUP(D12*E12/$N$3,基础数据!$O$37:$O$46,基础数据!$K$37:$K$46,"建议桥架敷设",1,1),$R$2="聚乙烯（PE）",_xlfn.XLOOKUP(D12*E12/$N$3,基础数据!$O$51:$O$62,基础数据!$K$51:$K$62,"建议桥架敷设",1,1),$R$2="双壁波纹管",_xlfn.XLOOKUP(D12*E12/$N$3,基础数据!$O$67:$O$72,基础数据!$K$67:$K$72,"建议桥架敷设",1,1),$R$2="套接扣压式薄壁钢导管（KBG）",_xlfn.XLOOKUP(D12*E12/$N$3,基础数据!$O$106:$O$110,基础数据!$K$106:$K$110,"建议桥架敷设",1,1)) -> - | G12: =天诚!B8 -> UTP-CAT.6 | H12: =天诚!C8 -> 6 | I12: =(H12/2)^2*PI() -> 28.274334 | K12: =_xlfn.IFS(J12=0,"-",$R$2="低压流体输送用焊接钢管（SC）",_xlfn.XLOOKUP(I12*J12/$N$3,基础数据!$O$4:$O$15,基础数据!$K$4:$K$15,"建议桥架敷设",1,1),$R$2="套接紧定式钢管（JDG）",_xlfn.XLOOKUP(I12*J12/$N$3,基础数据!$O$16:$O$21,基础数据!$K$16:$K$21,"建议桥架敷设",1,1),$R$2="聚氯乙烯硬质电线管（PC）",_xlfn.XLOOKUP(I12*J12/$N$3,基础数据!$O$22:$O$27,基础数据!$K$22:$K$27,"建议桥架敷设",1,1),$R$2="聚氯乙烯半硬质电线管（FPC）",_xlfn.XLOOKUP(I12*J12/$N$3,基础数据!$O$28:$O$33,基础数据!$K$28:$K$33,"建议桥架敷设",1,1),$R$2="聚氯乙烯（PVC-U）",_xlfn.XLOOKUP(I12*J12/$N$3,基础数据!$O$37:$O$46,基础数据!$K$37:$K$46,"建议桥架敷设",1,1),$R$2="聚乙烯（PE）",_xlfn.XLOOKUP(I12*J12/$N$3,基础数据!$O$51:$O$62,基础数据!$K$51:$K$62,"建议桥架敷设",1,1),$R$2="双壁波纹管",_xlfn.XLOOKUP(I12*J12/$N$3,基础数据!$O$67:$O$72,基础数据!$K$67:$K$72,"建议桥架敷设",1,1),$R$2="套接扣压式薄壁钢导管（KBG）",_xlfn.XLOOKUP(I12*J12/$N$3,基础数据!$O$106:$O$110,基础数据!$K$106:$K$110,"建议桥架敷设",1,1)) -> - | L12: =飞鹤!A21 -> RVV-2*1.5 | M12: =飞鹤!B21 -> 8.6 | N12: =(M12/2)^2*PI() -> 58.088048 | P12: =_xlfn.IFS(O12=0,"-",$R$2="低压流体输送用焊接钢管（SC）",_xlfn.XLOOKUP(N12*O12/$N$3,基础数据!$O$4:$O$15,基础数据!$K$4:$K$15,"建议桥架敷设",1,1),$R$2="套接紧定式钢管（JDG）",_xlfn.XLOOKUP(N12*O12/$N$3,基础数据!$O$16:$O$21,基础数据!$K$16:$K$21,"建议桥架敷设",1,1),$R$2="聚氯乙烯硬质电线管（PC）",_xlfn.XLOOKUP(N12*O12/$N$3,基础数据!$O$22:$O$27,基础数据!$K$22:$K$27,"建议桥架敷设",1,1),$R$2="聚氯乙烯半硬质电线管（FPC）",_xlfn.XLOOKUP(N12*O12/$N$3,基础数据!$O$28:$O$33,基础数据!$K$28:$K$33,"建议桥架敷设",1,1),$R$2="聚氯乙烯（PVC-U）",_xlfn.XLOOKUP(N12*O12/$N$3,基础数据!$O$37:$O$46,基础数据!$K$37:$K$46,"建议桥架敷设",1,1),$R$2="聚乙烯（PE）",_xlfn.XLOOKUP(N12*O12/$N$3,基础数据!$O$51:$O$62,基础数据!$K$51:$K$62,"建议桥架敷设",1,1),$R$2="双壁波纹管",_xlfn.XLOOKUP(N12*O12/$N$3,基础数据!$O$67:$O$72,基础数据!$K$67:$K$72,"建议桥架敷设",1,1),$R$2="套接扣压式薄壁钢导管（KBG）",_xlfn.XLOOKUP(N12*O12/$N$3,基础数据!$O$106:$O$110,基础数据!$K$106:$K$110,"建议桥架敷设",1,1)) -> - | Q12: =飞鹤!A89 -> RVVP-2*1.5 | R12: =飞鹤!B89 -> 9.2 | S12: =(R12/2)^2*PI() -> 66.476101 | U12: =_xlfn.IFS(T12=0,"-",$R$2="低压流体输送用焊接钢管（SC）",_xlfn.XLOOKUP(S12*T12/$N$3,基础数据!$O$4:$O$15,基础数据!$K$4:$K$15,"建议桥架敷设",1,1),$R$2="套接紧定式钢管（JDG）",_xlfn.XLOOKUP(S12*T12/$N$3,基础数据!$O$16:$O$21,基础数据!$K$16:$K$21,"建议桥架敷设",1,1),$R$2="聚氯乙烯硬质电线管（PC）",_xlfn.XLOOKUP(S12*T12/$N$3,基础数据!$O$22:$O$27,基础数据!$K$22:$K$27,"建议桥架敷设",1,1),$R$2="聚氯乙烯半硬质电线管（FPC）",_xlfn.XLOOKUP(S12*T12/$N$3,基础数据!$O$28:$O$33,基础数据!$K$28:$K$33,"建议桥架敷设",1,1),$R$2="聚氯乙烯（PVC-U）",_xlfn.XLOOKUP(S12*T12/$N$3,基础数据!$O$37:$O$46,基础数据!$K$37:$K$46,"建议桥架敷设",1,1),$R$2="聚乙烯（PE）",_xlfn.XLOOKUP(S12*T12/$N$3,基础数据!$O$51:$O$62,基础数据!$K$51:$K$62,"建议桥架敷设",1,1),$R$2="双壁波纹管",_xlfn.XLOOKUP(S12*T12/$N$3,基础数据!$O$67:$O$72,基础数据!$K$67:$K$72,"建议桥架敷设",1,1),$R$2="套接扣压式薄壁钢导管（KBG）",_xlfn.XLOOKUP(S12*T12/$N$3,基础数据!$O$106:$O$110,基础数据!$K$106:$K$110,"建议桥架敷设",1,1)) -> - | V12: =天诚!B68 -> HTP-2*48/0.10 | W12: =天诚!C68 -> 6 | X12: =(W12/2)^2*PI() -> 28.274334 | Z12: =_xlfn.IFS(Y12=0,"-",$R$2="低压流体输送用焊接钢管（SC）",_xlfn.XLOOKUP(X12*Y12/$N$3,基础数据!$O$4:$O$15,基础数据!$K$4:$K$15,"建议桥架敷设",1,1),$R$2="套接紧定式钢管（JDG）",_xlfn.XLOOKUP(X12*Y12/$N$3,基础数据!$O$16:$O$21,基础数据!$K$16:$K$21,"建议桥架敷设",1,1),$R$2="聚氯乙烯硬质电线管（PC）",_xlfn.XLOOKUP(X12*Y12/$N$3,基础数据!$O$22:$O$27,基础数据!$K$22:$K$27,"建议桥架敷设",1,1),$R$2="聚氯乙烯半硬质电线管（FPC）",_xlfn.XLOOKUP(X12*Y12/$N$3,基础数据!$O$28:$O$33,基础数据!$K$28:$K$33,"建议桥架敷设",1,1),$R$2="聚氯乙烯（PVC-U）",_xlfn.XLOOKUP(X12*Y12/$N$3,基础数据!$O$37:$O$46,基础数据!$K$37:$K$46,"建议桥架敷设",1,1),$R$2="聚乙烯（PE）",_xlfn.XLOOKUP(X12*Y12/$N$3,基础数据!$O$51:$O$62,基础数据!$K$51:$K$62,"建议桥架敷设",1,1),$R$2="双壁波纹管",_xlfn.XLOOKUP(X12*Y12/$N$3,基础数据!$O$67:$O$72,基础数据!$K$67:$K$72,"建议桥架敷设",1,1),$R$2="套接扣压式薄壁钢导管（KBG）",_xlfn.XLOOKUP(X12*Y12/$N$3,基础数据!$O$106:$O$110,基础数据!$K$106:$K$110,"建议桥架敷设",1,1)) -> -
B13: =长飞!A6 -> 8芯室内光缆 | C13: =长飞!B6 -> 5.6 | D13: =(C13/2)^2*PI() -> 24.630086 | F13: =_xlfn.IFS(E13=0,"-",$R$2="低压流体输送用焊接钢管（SC）",_xlfn.XLOOKUP(D13*E13/$N$3,基础数据!$O$4:$O$15,基础数据!$K$4:$K$15,"建议桥架敷设",1,1),$R$2="套接紧定式钢管（JDG）",_xlfn.XLOOKUP(D13*E13/$N$3,基础数据!$O$16:$O$21,基础数据!$K$16:$K$21,"建议桥架敷设",1,1),$R$2="聚氯乙烯硬质电线管（PC）",_xlfn.XLOOKUP(D13*E13/$N$3,基础数据!$O$22:$O$27,基础数据!$K$22:$K$27,"建议桥架敷设",1,1),$R$2="聚氯乙烯半硬质电线管（FPC）",_xlfn.XLOOKUP(D13*E13/$N$3,基础数据!$O$28:$O$33,基础数据!$K$28:$K$33,"建议桥架敷设",1,1),$R$2="聚氯乙烯（PVC-U）",_xlfn.XLOOKUP(D13*E13/$N$3,基础数据!$O$37:$O$46,基础数据!$K$37:$K$46,"建议桥架敷设",1,1),$R$2="聚乙烯（PE）",_xlfn.XLOOKUP(D13*E13/$N$3,基础数据!$O$51:$O$62,基础数据!$K$51:$K$62,"建议桥架敷设",1,1),$R$2="双壁波纹管",_xlfn.XLOOKUP(D13*E13/$N$3,基础数据!$O$67:$O$72,基础数据!$K$67:$K$72,"建议桥架敷设",1,1),$R$2="套接扣压式薄壁钢导管（KBG）",_xlfn.XLOOKUP(D13*E13/$N$3,基础数据!$O$106:$O$110,基础数据!$K$106:$K$110,"建议桥架敷设",1,1)) -> - | G13: =天诚!B12 -> FTP-CAT.6 | H13: =天诚!C12 -> 7.6 | I13: =(H13/2)^2*PI() -> 45.364598 | K13: =_xlfn.IFS(J13=0,"-",$R$2="低压流体输送用焊接钢管（SC）",_xlfn.XLOOKUP(I13*J13/$N$3,基础数据!$O$4:$O$15,基础数据!$K$4:$K$15,"建议桥架敷设",1,1),$R$2="套接紧定式钢管（JDG）",_xlfn.XLOOKUP(I13*J13/$N$3,基础数据!$O$16:$O$21,基础数据!$K$16:$K$21,"建议桥架敷设",1,1),$R$2="聚氯乙烯硬质电线管（PC）",_xlfn.XLOOKUP(I13*J13/$N$3,基础数据!$O$22:$O$27,基础数据!$K$22:$K$27,"建议桥架敷设",1,1),$R$2="聚氯乙烯半硬质电线管（FPC）",_xlfn.XLOOKUP(I13*J13/$N$3,基础数据!$O$28:$O$33,基础数据!$K$28:$K$33,"建议桥架敷设",1,1),$R$2="聚氯乙烯（PVC-U）",_xlfn.XLOOKUP(I13*J13/$N$3,基础数据!$O$37:$O$46,基础数据!$K$37:$K$46,"建议桥架敷设",1,1),$R$2="聚乙烯（PE）",_xlfn.XLOOKUP(I13*J13/$N$3,基础数据!$O$51:$O$62,基础数据!$K$51:$K$62,"建议桥架敷设",1,1),$R$2="双壁波纹管",_xlfn.XLOOKUP(I13*J13/$N$3,基础数据!$O$67:$O$72,基础数据!$K$67:$K$72,"建议桥架敷设",1,1),$R$2="套接扣压式薄壁钢导管（KBG）",_xlfn.XLOOKUP(I13*J13/$N$3,基础数据!$O$106:$O$110,基础数据!$K$106:$K$110,"建议桥架敷设",1,1)) -> - | L13: =飞鹤!A22 -> RVV-2*2.5 | M13: =飞鹤!B22 -> 10.6 | N13: =(M13/2)^2*PI() -> 88.247338 | P13: =_xlfn.IFS(O13=0,"-",$R$2="低压流体输送用焊接钢管（SC）",_xlfn.XLOOKUP(N13*O13/$N$3,基础数据!$O$4:$O$15,基础数据!$K$4:$K$15,"建议桥架敷设",1,1),$R$2="套接紧定式钢管（JDG）",_xlfn.XLOOKUP(N13*O13/$N$3,基础数据!$O$16:$O$21,基础数据!$K$16:$K$21,"建议桥架敷设",1,1),$R$2="聚氯乙烯硬质电线管（PC）",_xlfn.XLOOKUP(N13*O13/$N$3,基础数据!$O$22:$O$27,基础数据!$K$22:$K$27,"建议桥架敷设",1,1),$R$2="聚氯乙烯半硬质电线管（FPC）",_xlfn.XLOOKUP(N13*O13/$N$3,基础数据!$O$28:$O$33,基础数据!$K$28:$K$33,"建议桥架敷设",1,1),$R$2="聚氯乙烯（PVC-U）",_xlfn.XLOOKUP(N13*O13/$N$3,基础数据!$O$37:$O$46,基础数据!$K$37:$K$46,"建议桥架敷设",1,1),$R$2="聚乙烯（PE）",_xlfn.XLOOKUP(N13*O13/$N$3,基础数据!$O$51:$O$62,基础数据!$K$51:$K$62,"建议桥架敷设",1,1),$R$2="双壁波纹管",_xlfn.XLOOKUP(N13*O13/$N$3,基础数据!$O$67:$O$72,基础数据!$K$67:$K$72,"建议桥架敷设",1,1),$R$2="套接扣压式薄壁钢导管（KBG）",_xlfn.XLOOKUP(N13*O13/$N$3,基础数据!$O$106:$O$110,基础数据!$K$106:$K$110,"建议桥架敷设",1,1)) -> - | Q13: =飞鹤!A90 -> RVVP-2*2.5 | R13: =飞鹤!B90 -> 11.7 | S13: =(R13/2)^2*PI() -> 107.51315 | U13: =_xlfn.IFS(T13=0,"-",$R$2="低压流体输送用焊接钢管（SC）",_xlfn.XLOOKUP(S13*T13/$N$3,基础数据!$O$4:$O$15,基础数据!$K$4:$K$15,"建议桥架敷设",1,1),$R$2="套接紧定式钢管（JDG）",_xlfn.XLOOKUP(S13*T13/$N$3,基础数据!$O$16:$O$21,基础数据!$K$16:$K$21,"建议桥架敷设",1,1),$R$2="聚氯乙烯硬质电线管（PC）",_xlfn.XLOOKUP(S13*T13/$N$3,基础数据!$O$22:$O$27,基础数据!$K$22:$K$27,"建议桥架敷设",1,1),$R$2="聚氯乙烯半硬质电线管（FPC）",_xlfn.XLOOKUP(S13*T13/$N$3,基础数据!$O$28:$O$33,基础数据!$K$28:$K$33,"建议桥架敷设",1,1),$R$2="聚氯乙烯（PVC-U）",_xlfn.XLOOKUP(S13*T13/$N$3,基础数据!$O$37:$O$46,基础数据!$K$37:$K$46,"建议桥架敷设",1,1),$R$2="聚乙烯（PE）",_xlfn.XLOOKUP(S13*T13/$N$3,基础数据!$O$51:$O$62,基础数据!$K$51:$K$62,"建议桥架敷设",1,1),$R$2="双壁波纹管",_xlfn.XLOOKUP(S13*T13/$N$3,基础数据!$O$67:$O$72,基础数据!$K$67:$K$72,"建议桥架敷设",1,1),$R$2="套接扣压式薄壁钢导管（KBG）",_xlfn.XLOOKUP(S13*T13/$N$3,基础数据!$O$106:$O$110,基础数据!$K$106:$K$110,"建议桥架敷设",1,1)) -> - | V13: =天诚!B69 -> HTP-3*20/0.10 | W13: =天诚!C69 -> 6.15 | X13: =(W13/2)^2*PI() -> 29.705722 | Z13: =_xlfn.IFS(Y13=0,"-",$R$2="低压流体输送用焊接钢管（SC）",_xlfn.XLOOKUP(X13*Y13/$N$3,基础数据!$O$4:$O$15,基础数据!$K$4:$K$15,"建议桥架敷设",1,1),$R$2="套接紧定式钢管（JDG）",_xlfn.XLOOKUP(X13*Y13/$N$3,基础数据!$O$16:$O$21,基础数据!$K$16:$K$21,"建议桥架敷设",1,1),$R$2="聚氯乙烯硬质电线管（PC）",_xlfn.XLOOKUP(X13*Y13/$N$3,基础数据!$O$22:$O$27,基础数据!$K$22:$K$27,"建议桥架敷设",1,1),$R$2="聚氯乙烯半硬质电线管（FPC）",_xlfn.XLOOKUP(X13*Y13/$N$3,基础数据!$O$28:$O$33,基础数据!$K$28:$K$33,"建议桥架敷设",1,1),$R$2="聚氯乙烯（PVC-U）",_xlfn.XLOOKUP(X13*Y13/$N$3,基础数据!$O$37:$O$46,基础数据!$K$37:$K$46,"建议桥架敷设",1,1),$R$2="聚乙烯（PE）",_xlfn.XLOOKUP(X13*Y13/$N$3,基础数据!$O$51:$O$62,基础数据!$K$51:$K$62,"建议桥架敷设",1,1),$R$2="双壁波纹管",_xlfn.XLOOKUP(X13*Y13/$N$3,基础数据!$O$67:$O$72,基础数据!$K$67:$K$72,"建议桥架敷设",1,1),$R$2="套接扣压式薄壁钢导管（KBG）",_xlfn.XLOOKUP(X13*Y13/$N$3,基础数据!$O$106:$O$110,基础数据!$K$106:$K$110,"建议桥架敷设",1,1)) -> -
B14: =长飞!A7 -> 12芯室内光缆 | C14: =长飞!B7 -> 6.2 | D14: =(C14/2)^2*PI() -> 30.190705 | F14: =_xlfn.IFS(E14=0,"-",E14=1,_xlfn.IFS($R$2="低压流体输送用焊接钢管（SC）",_xlfn.XLOOKUP(C14/$N$2,基础数据!$N$4:$N$15,基础数据!$K$4:$K$15,"建议桥架敷设",1,1),$R$2="套接紧定式钢管（JDG）",_xlfn.XLOOKUP(C14/$N$2,基础数据!$N$16:$N$21,基础数据!$K$16:$K$21,"建议桥架敷设",1,1),$R$2="聚氯乙烯硬质电线管（PC）",_xlfn.XLOOKUP(C14/$N$2,基础数据!$N$22:$N$27,基础数据!$K$22:$K$27,"建议桥架敷设",1,1),$R$2="聚氯乙烯半硬质电线管（FPC）",_xlfn.XLOOKUP(C14/$N$2,基础数据!$N$28:$N$33,基础数据!$K$28:$K$33,"建议桥架敷设",1,1),$R$2="聚氯乙烯（PVC-U）",_xlfn.XLOOKUP(C14/$N$2,基础数据!$N$37:$N$46,基础数据!$K$37:$K$46,"建议桥架敷设",1,1),$R$2="聚乙烯（PE）",_xlfn.XLOOKUP(C14/$N$2,基础数据!$N$51:$N$62,基础数据!$K$51:$K$62,"建议桥架敷设",1,1),$R$2="双壁波纹管",_xlfn.XLOOKUP(C14/$N$2,基础数据!$N$67:$N$72,基础数据!$K$67:$K$72,"建议桥架敷设",1,1),$R$2="套接扣压式薄壁钢导管（KBG）",_xlfn.XLOOKUP(C14/$N$2,基础数据!$N$106:$N$110,基础数据!$K$106:$K$110,"建议桥架敷设",1,1)),$R$2="低压流体输送用焊接钢管（SC）",_xlfn.XLOOKUP(D14*E14/$N$3,基础数据!$O$4:$O$15,基础数据!$K$4:$K$15,"建议桥架敷设",1,1),$R$2="套接紧定式钢管（JDG）",_xlfn.XLOOKUP(D14*E14/$N$3,基础数据!$O$16:$O$21,基础数据!$K$16:$K$21,"建议桥架敷设",1,1),$R$2="聚氯乙烯硬质电线管（PC）",_xlfn.XLOOKUP(D14*E14/$N$3,基础数据!$O$22:$O$27,基础数据!$K$22:$K$27,"建议桥架敷设",1,1),$R$2="聚氯乙烯半硬质电线管（FPC）",_xlfn.XLOOKUP(D14*E14/$N$3,基础数据!$O$28:$O$33,基础数据!$K$28:$K$33,"建议桥架敷设",1,1),$R$2="聚氯乙烯（PVC-U）",_xlfn.XLOOKUP(D14*E14/$N$3,基础数据!$O$37:$O$46,基础数据!$K$37:$K$46,"建议桥架敷设",1,1),$R$2="聚乙烯（PE）",_xlfn.XLOOKUP(D14*E14/$N$3,基础数据!$O$51:$O$62,基础数据!$K$51:$K$62,"建议桥架敷设",1,1),$R$2="双壁波纹管",_xlfn.XLOOKUP(D14*E14/$N$3,基础数据!$O$67:$O$72,基础数据!$K$67:$K$72,"建议桥架敷设",1,1),$R$2="套接扣压式薄壁钢导管（KBG）",_xlfn.XLOOKUP(D14*E14/$N$3,基础数据!$O$106:$O$110,基础数据!$K$106:$K$110,"建议桥架敷设",1,1)) -> - | G14: =天诚!B15 -> U/FTP-CAT.6 | H14: =天诚!C15 -> 8 | I14: =(H14/2)^2*PI() -> 50.265482 | K14: =_xlfn.IFS(J14=0,"-",$R$2="低压流体输送用焊接钢管（SC）",_xlfn.XLOOKUP(I14*J14/$N$3,基础数据!$O$4:$O$15,基础数据!$K$4:$K$15,"建议桥架敷设",1,1),$R$2="套接紧定式钢管（JDG）",_xlfn.XLOOKUP(I14*J14/$N$3,基础数据!$O$16:$O$21,基础数据!$K$16:$K$21,"建议桥架敷设",1,1),$R$2="聚氯乙烯硬质电线管（PC）",_xlfn.XLOOKUP(I14*J14/$N$3,基础数据!$O$22:$O$27,基础数据!$K$22:$K$27,"建议桥架敷设",1,1),$R$2="聚氯乙烯半硬质电线管（FPC）",_xlfn.XLOOKUP(I14*J14/$N$3,基础数据!$O$28:$O$33,基础数据!$K$28:$K$33,"建议桥架敷设",1,1),$R$2="聚氯乙烯（PVC-U）",_xlfn.XLOOKUP(I14*J14/$N$3,基础数据!$O$37:$O$46,基础数据!$K$37:$K$46,"建议桥架敷设",1,1),$R$2="聚乙烯（PE）",_xlfn.XLOOKUP(I14*J14/$N$3,基础数据!$O$51:$O$62,基础数据!$K$51:$K$62,"建议桥架敷设",1,1),$R$2="双壁波纹管",_xlfn.XLOOKUP(I14*J14/$N$3,基础数据!$O$67:$O$72,基础数据!$K$67:$K$72,"建议桥架敷设",1,1),$R$2="套接扣压式薄壁钢导管（KBG）",_xlfn.XLOOKUP(I14*J14/$N$3,基础数据!$O$106:$O$110,基础数据!$K$106:$K$110,"建议桥架敷设",1,1)) -> - | N14: =(M14/2)^2*PI() -> 0 | P14: =_xlfn.IFS(O14=0,"-",$R$2="低压流体输送用焊接钢管（SC）",_xlfn.XLOOKUP(N14*O14/$N$3,基础数据!$O$4:$O$15,基础数据!$K$4:$K$15,"建议桥架敷设",1,1),$R$2="套接紧定式钢管（JDG）",_xlfn.XLOOKUP(N14*O14/$N$3,基础数据!$O$16:$O$21,基础数据!$K$16:$K$21,"建议桥架敷设",1,1),$R$2="聚氯乙烯硬质电线管（PC）",_xlfn.XLOOKUP(N14*O14/$N$3,基础数据!$O$22:$O$27,基础数据!$K$22:$K$27,"建议桥架敷设",1,1),$R$2="聚氯乙烯半硬质电线管（FPC）",_xlfn.XLOOKUP(N14*O14/$N$3,基础数据!$O$28:$O$33,基础数据!$K$28:$K$33,"建议桥架敷设",1,1),$R$2="聚氯乙烯（PVC-U）",_xlfn.XLOOKUP(N14*O14/$N$3,基础数据!$O$37:$O$46,基础数据!$K$37:$K$46,"建议桥架敷设",1,1),$R$2="聚乙烯（PE）",_xlfn.XLOOKUP(N14*O14/$N$3,基础数据!$O$51:$O$62,基础数据!$K$51:$K$62,"建议桥架敷设",1,1),$R$2="双壁波纹管",_xlfn.XLOOKUP(N14*O14/$N$3,基础数据!$O$67:$O$72,基础数据!$K$67:$K$72,"建议桥架敷设",1,1),$R$2="套接扣压式薄壁钢导管（KBG）",_xlfn.XLOOKUP(N14*O14/$N$3,基础数据!$O$106:$O$110,基础数据!$K$106:$K$110,"建议桥架敷设",1,1)) -> - | Q14: =飞鹤!A102 -> RVVP-4*0.5 | R14: =飞鹤!B102 -> 8.9 | S14: =(R14/2)^2*PI() -> 62.211389 | U14: =_xlfn.IFS(T14=0,"-",$R$2="低压流体输送用焊接钢管（SC）",_xlfn.XLOOKUP(S14*T14/$N$3,基础数据!$O$4:$O$15,基础数据!$K$4:$K$15,"建议桥架敷设",1,1),$R$2="套接紧定式钢管（JDG）",_xlfn.XLOOKUP(S14*T14/$N$3,基础数据!$O$16:$O$21,基础数据!$K$16:$K$21,"建议桥架敷设",1,1),$R$2="聚氯乙烯硬质电线管（PC）",_xlfn.XLOOKUP(S14*T14/$N$3,基础数据!$O$22:$O$27,基础数据!$K$22:$K$27,"建议桥架敷设",1,1),$R$2="聚氯乙烯半硬质电线管（FPC）",_xlfn.XLOOKUP(S14*T14/$N$3,基础数据!$O$28:$O$33,基础数据!$K$28:$K$33,"建议桥架敷设",1,1),$R$2="聚氯乙烯（PVC-U）",_xlfn.XLOOKUP(S14*T14/$N$3,基础数据!$O$37:$O$46,基础数据!$K$37:$K$46,"建议桥架敷设",1,1),$R$2="聚乙烯（PE）",_xlfn.XLOOKUP(S14*T14/$N$3,基础数据!$O$51:$O$62,基础数据!$K$51:$K$62,"建议桥架敷设",1,1),$R$2="双壁波纹管",_xlfn.XLOOKUP(S14*T14/$N$3,基础数据!$O$67:$O$72,基础数据!$K$67:$K$72,"建议桥架敷设",1,1),$R$2="套接扣压式薄壁钢导管（KBG）",_xlfn.XLOOKUP(S14*T14/$N$3,基础数据!$O$106:$O$110,基础数据!$K$106:$K$110,"建议桥架敷设",1,1)) -> - | V14: =天诚!B70 -> HTP-3*27/0.10 | W14: =天诚!C70 -> 6.05 | X14: =(W14/2)^2*PI() -> 28.747536 | Z14: =_xlfn.IFS(Y14=0,"-",$R$2="低压流体输送用焊接钢管（SC）",_xlfn.XLOOKUP(X14*Y14/$N$3,基础数据!$O$4:$O$15,基础数据!$K$4:$K$15,"建议桥架敷设",1,1),$R$2="套接紧定式钢管（JDG）",_xlfn.XLOOKUP(X14*Y14/$N$3,基础数据!$O$16:$O$21,基础数据!$K$16:$K$21,"建议桥架敷设",1,1),$R$2="聚氯乙烯硬质电线管（PC）",_xlfn.XLOOKUP(X14*Y14/$N$3,基础数据!$O$22:$O$27,基础数据!$K$22:$K$27,"建议桥架敷设",1,1),$R$2="聚氯乙烯半硬质电线管（FPC）",_xlfn.XLOOKUP(X14*Y14/$N$3,基础数据!$O$28:$O$33,基础数据!$K$28:$K$33,"建议桥架敷设",1,1),$R$2="聚氯乙烯（PVC-U）",_xlfn.XLOOKUP(X14*Y14/$N$3,基础数据!$O$37:$O$46,基础数据!$K$37:$K$46,"建议桥架敷设",1,1),$R$2="聚乙烯（PE）",_xlfn.XLOOKUP(X14*Y14/$N$3,基础数据!$O$51:$O$62,基础数据!$K$51:$K$62,"建议桥架敷设",1,1),$R$2="双壁波纹管",_xlfn.XLOOKUP(X14*Y14/$N$3,基础数据!$O$67:$O$72,基础数据!$K$67:$K$72,"建议桥架敷设",1,1),$R$2="套接扣压式薄壁钢导管（KBG）",_xlfn.XLOOKUP(X14*Y14/$N$3,基础数据!$O$106:$O$110,基础数据!$K$106:$K$110,"建议桥架敷设",1,1)) -> -
B15: =长飞!A8 -> 24芯室内光缆 | C15: =长飞!B8 -> 8.1 | D15: =(C15/2)^2*PI() -> 51.529974 | F15: =_xlfn.IFS(E15=0,"-",E15=1,_xlfn.IFS($R$2="低压流体输送用焊接钢管（SC）",_xlfn.XLOOKUP(C15/$N$2,基础数据!$N$4:$N$15,基础数据!$K$4:$K$15,"建议桥架敷设",1,1),$R$2="套接紧定式钢管（JDG）",_xlfn.XLOOKUP(C15/$N$2,基础数据!$N$16:$N$21,基础数据!$K$16:$K$21,"建议桥架敷设",1,1),$R$2="聚氯乙烯硬质电线管（PC）",_xlfn.XLOOKUP(C15/$N$2,基础数据!$N$22:$N$27,基础数据!$K$22:$K$27,"建议桥架敷设",1,1),$R$2="聚氯乙烯半硬质电线管（FPC）",_xlfn.XLOOKUP(C15/$N$2,基础数据!$N$28:$N$33,基础数据!$K$28:$K$33,"建议桥架敷设",1,1),$R$2="聚氯乙烯（PVC-U）",_xlfn.XLOOKUP(C15/$N$2,基础数据!$N$37:$N$46,基础数据!$K$37:$K$46,"建议桥架敷设",1,1),$R$2="聚乙烯（PE）",_xlfn.XLOOKUP(C15/$N$2,基础数据!$N$51:$N$62,基础数据!$K$51:$K$62,"建议桥架敷设",1,1),$R$2="双壁波纹管",_xlfn.XLOOKUP(C15/$N$2,基础数据!$N$67:$N$72,基础数据!$K$67:$K$72,"建议桥架敷设",1,1),$R$2="套接扣压式薄壁钢导管（KBG）",_xlfn.XLOOKUP(C15/$N$2,基础数据!$N$106:$N$110,基础数据!$K$106:$K$110,"建议桥架敷设",1,1)),$R$2="低压流体输送用焊接钢管（SC）",_xlfn.XLOOKUP(D15*E15/$N$3,基础数据!$O$4:$O$15,基础数据!$K$4:$K$15,"建议桥架敷设",1,1),$R$2="套接紧定式钢管（JDG）",_xlfn.XLOOKUP(D15*E15/$N$3,基础数据!$O$16:$O$21,基础数据!$K$16:$K$21,"建议桥架敷设",1,1),$R$2="聚氯乙烯硬质电线管（PC）",_xlfn.XLOOKUP(D15*E15/$N$3,基础数据!$O$22:$O$27,基础数据!$K$22:$K$27,"建议桥架敷设",1,1),$R$2="聚氯乙烯半硬质电线管（FPC）",_xlfn.XLOOKUP(D15*E15/$N$3,基础数据!$O$28:$O$33,基础数据!$K$28:$K$33,"建议桥架敷设",1,1),$R$2="聚氯乙烯（PVC-U）",_xlfn.XLOOKUP(D15*E15/$N$3,基础数据!$O$37:$O$46,基础数据!$K$37:$K$46,"建议桥架敷设",1,1),$R$2="聚乙烯（PE）",_xlfn.XLOOKUP(D15*E15/$N$3,基础数据!$O$51:$O$62,基础数据!$K$51:$K$62,"建议桥架敷设",1,1),$R$2="双壁波纹管",_xlfn.XLOOKUP(D15*E15/$N$3,基础数据!$O$67:$O$72,基础数据!$K$67:$K$72,"建议桥架敷设",1,1),$R$2="套接扣压式薄壁钢导管（KBG）",_xlfn.XLOOKUP(D15*E15/$N$3,基础数据!$O$106:$O$110,基础数据!$K$106:$K$110,"建议桥架敷设",1,1)) -> - | G15: =天诚!B16 -> SFTP-CAT.6 | H15: =天诚!C16 -> 8 | I15: =(H15/2)^2*PI() -> 50.265482 | K15: =_xlfn.IFS(J15=0,"-",$R$2="低压流体输送用焊接钢管（SC）",_xlfn.XLOOKUP(I15*J15/$N$3,基础数据!$O$4:$O$15,基础数据!$K$4:$K$15,"建议桥架敷设",1,1),$R$2="套接紧定式钢管（JDG）",_xlfn.XLOOKUP(I15*J15/$N$3,基础数据!$O$16:$O$21,基础数据!$K$16:$K$21,"建议桥架敷设",1,1),$R$2="聚氯乙烯硬质电线管（PC）",_xlfn.XLOOKUP(I15*J15/$N$3,基础数据!$O$22:$O$27,基础数据!$K$22:$K$27,"建议桥架敷设",1,1),$R$2="聚氯乙烯半硬质电线管（FPC）",_xlfn.XLOOKUP(I15*J15/$N$3,基础数据!$O$28:$O$33,基础数据!$K$28:$K$33,"建议桥架敷设",1,1),$R$2="聚氯乙烯（PVC-U）",_xlfn.XLOOKUP(I15*J15/$N$3,基础数据!$O$37:$O$46,基础数据!$K$37:$K$46,"建议桥架敷设",1,1),$R$2="聚乙烯（PE）",_xlfn.XLOOKUP(I15*J15/$N$3,基础数据!$O$51:$O$62,基础数据!$K$51:$K$62,"建议桥架敷设",1,1),$R$2="双壁波纹管",_xlfn.XLOOKUP(I15*J15/$N$3,基础数据!$O$67:$O$72,基础数据!$K$67:$K$72,"建议桥架敷设",1,1),$R$2="套接扣压式薄壁钢导管（KBG）",_xlfn.XLOOKUP(I15*J15/$N$3,基础数据!$O$106:$O$110,基础数据!$K$106:$K$110,"建议桥架敷设",1,1)) -> - | L15: =飞鹤!A26 -> RVV-4*0.75 | M15: =飞鹤!B26 -> 8.3 | N15: =(M15/2)^2*PI() -> 54.106079 | P15: =_xlfn.IFS(O15=0,"-",$R$2="低压流体输送用焊接钢管（SC）",_xlfn.XLOOKUP(N15*O15/$N$3,基础数据!$O$4:$O$15,基础数据!$K$4:$K$15,"建议桥架敷设",1,1),$R$2="套接紧定式钢管（JDG）",_xlfn.XLOOKUP(N15*O15/$N$3,基础数据!$O$16:$O$21,基础数据!$K$16:$K$21,"建议桥架敷设",1,1),$R$2="聚氯乙烯硬质电线管（PC）",_xlfn.XLOOKUP(N15*O15/$N$3,基础数据!$O$22:$O$27,基础数据!$K$22:$K$27,"建议桥架敷设",1,1),$R$2="聚氯乙烯半硬质电线管（FPC）",_xlfn.XLOOKUP(N15*O15/$N$3,基础数据!$O$28:$O$33,基础数据!$K$28:$K$33,"建议桥架敷设",1,1),$R$2="聚氯乙烯（PVC-U）",_xlfn.XLOOKUP(N15*O15/$N$3,基础数据!$O$37:$O$46,基础数据!$K$37:$K$46,"建议桥架敷设",1,1),$R$2="聚乙烯（PE）",_xlfn.XLOOKUP(N15*O15/$N$3,基础数据!$O$51:$O$62,基础数据!$K$51:$K$62,"建议桥架敷设",1,1),$R$2="双壁波纹管",_xlfn.XLOOKUP(N15*O15/$N$3,基础数据!$O$67:$O$72,基础数据!$K$67:$K$72,"建议桥架敷设",1,1),$R$2="套接扣压式薄壁钢导管（KBG）",_xlfn.XLOOKUP(N15*O15/$N$3,基础数据!$O$106:$O$110,基础数据!$K$106:$K$110,"建议桥架敷设",1,1)) -> - | Q15: =飞鹤!A103 -> RVVP-4*0.75 | R15: =飞鹤!B103 -> 9.3 | S15: =(R15/2)^2*PI() -> 67.929087 | U15: =_xlfn.IFS(T15=0,"-",$R$2="低压流体输送用焊接钢管（SC）",_xlfn.XLOOKUP(S15*T15/$N$3,基础数据!$O$4:$O$15,基础数据!$K$4:$K$15,"建议桥架敷设",1,1),$R$2="套接紧定式钢管（JDG）",_xlfn.XLOOKUP(S15*T15/$N$3,基础数据!$O$16:$O$21,基础数据!$K$16:$K$21,"建议桥架敷设",1,1),$R$2="聚氯乙烯硬质电线管（PC）",_xlfn.XLOOKUP(S15*T15/$N$3,基础数据!$O$22:$O$27,基础数据!$K$22:$K$27,"建议桥架敷设",1,1),$R$2="聚氯乙烯半硬质电线管（FPC）",_xlfn.XLOOKUP(S15*T15/$N$3,基础数据!$O$28:$O$33,基础数据!$K$28:$K$33,"建议桥架敷设",1,1),$R$2="聚氯乙烯（PVC-U）",_xlfn.XLOOKUP(S15*T15/$N$3,基础数据!$O$37:$O$46,基础数据!$K$37:$K$46,"建议桥架敷设",1,1),$R$2="聚乙烯（PE）",_xlfn.XLOOKUP(S15*T15/$N$3,基础数据!$O$51:$O$62,基础数据!$K$51:$K$62,"建议桥架敷设",1,1),$R$2="双壁波纹管",_xlfn.XLOOKUP(S15*T15/$N$3,基础数据!$O$67:$O$72,基础数据!$K$67:$K$72,"建议桥架敷设",1,1),$R$2="套接扣压式薄壁钢导管（KBG）",_xlfn.XLOOKUP(S15*T15/$N$3,基础数据!$O$106:$O$110,基础数据!$K$106:$K$110,"建议桥架敷设",1,1)) -> - | X15: =(W15/2)^2*PI() -> 0 | Z15: =_xlfn.IFS(Y15=0,"-",$R$2="低压流体输送用焊接钢管（SC）",_xlfn.XLOOKUP(X15*Y15/$N$3,基础数据!$O$4:$O$15,基础数据!$K$4:$K$15,"建议桥架敷设",1,1),$R$2="套接紧定式钢管（JDG）",_xlfn.XLOOKUP(X15*Y15/$N$3,基础数据!$O$16:$O$21,基础数据!$K$16:$K$21,"建议桥架敷设",1,1),$R$2="聚氯乙烯硬质电线管（PC）",_xlfn.XLOOKUP(X15*Y15/$N$3,基础数据!$O$22:$O$27,基础数据!$K$22:$K$27,"建议桥架敷设",1,1),$R$2="聚氯乙烯半硬质电线管（FPC）",_xlfn.XLOOKUP(X15*Y15/$N$3,基础数据!$O$28:$O$33,基础数据!$K$28:$K$33,"建议桥架敷设",1,1),$R$2="聚氯乙烯（PVC-U）",_xlfn.XLOOKUP(X15*Y15/$N$3,基础数据!$O$37:$O$46,基础数据!$K$37:$K$46,"建议桥架敷设",1,1),$R$2="聚乙烯（PE）",_xlfn.XLOOKUP(X15*Y15/$N$3,基础数据!$O$51:$O$62,基础数据!$K$51:$K$62,"建议桥架敷设",1,1),$R$2="双壁波纹管",_xlfn.XLOOKUP(X15*Y15/$N$3,基础数据!$O$67:$O$72,基础数据!$K$67:$K$72,"建议桥架敷设",1,1),$R$2="套接扣压式薄壁钢导管（KBG）",_xlfn.XLOOKUP(X15*Y15/$N$3,基础数据!$O$106:$O$110,基础数据!$K$106:$K$110,"建议桥架敷设",1,1)) -> -
B16: =长飞!A9 -> 36芯室内光缆 | C16: =长飞!B9 -> 14.5 | D16: =(C16/2)^2*PI() -> 165.12996 | F16: =_xlfn.IFS(E16=0,"-",E16=1,_xlfn.IFS($R$2="低压流体输送用焊接钢管（SC）",_xlfn.XLOOKUP(C16/$N$2,基础数据!$N$4:$N$15,基础数据!$K$4:$K$15,"建议桥架敷设",1,1),$R$2="套接紧定式钢管（JDG）",_xlfn.XLOOKUP(C16/$N$2,基础数据!$N$16:$N$21,基础数据!$K$16:$K$21,"建议桥架敷设",1,1),$R$2="聚氯乙烯硬质电线管（PC）",_xlfn.XLOOKUP(C16/$N$2,基础数据!$N$22:$N$27,基础数据!$K$22:$K$27,"建议桥架敷设",1,1),$R$2="聚氯乙烯半硬质电线管（FPC）",_xlfn.XLOOKUP(C16/$N$2,基础数据!$N$28:$N$33,基础数据!$K$28:$K$33,"建议桥架敷设",1,1),$R$2="聚氯乙烯（PVC-U）",_xlfn.XLOOKUP(C16/$N$2,基础数据!$N$37:$N$46,基础数据!$K$37:$K$46,"建议桥架敷设",1,1),$R$2="聚乙烯（PE）",_xlfn.XLOOKUP(C16/$N$2,基础数据!$N$51:$N$62,基础数据!$K$51:$K$62,"建议桥架敷设",1,1),$R$2="双壁波纹管",_xlfn.XLOOKUP(C16/$N$2,基础数据!$N$67:$N$72,基础数据!$K$67:$K$72,"建议桥架敷设",1,1),$R$2="套接扣压式薄壁钢导管（KBG）",_xlfn.XLOOKUP(C16/$N$2,基础数据!$N$106:$N$110,基础数据!$K$106:$K$110,"建议桥架敷设",1,1)),$R$2="低压流体输送用焊接钢管（SC）",_xlfn.XLOOKUP(D16*E16/$N$3,基础数据!$O$4:$O$15,基础数据!$K$4:$K$15,"建议桥架敷设",1,1),$R$2="套接紧定式钢管（JDG）",_xlfn.XLOOKUP(D16*E16/$N$3,基础数据!$O$16:$O$21,基础数据!$K$16:$K$21,"建议桥架敷设",1,1),$R$2="聚氯乙烯硬质电线管（PC）",_xlfn.XLOOKUP(D16*E16/$N$3,基础数据!$O$22:$O$27,基础数据!$K$22:$K$27,"建议桥架敷设",1,1),$R$2="聚氯乙烯半硬质电线管（FPC）",_xlfn.XLOOKUP(D16*E16/$N$3,基础数据!$O$28:$O$33,基础数据!$K$28:$K$33,"建议桥架敷设",1,1),$R$2="聚氯乙烯（PVC-U）",_xlfn.XLOOKUP(D16*E16/$N$3,基础数据!$O$37:$O$46,基础数据!$K$37:$K$46,"建议桥架敷设",1,1),$R$2="聚乙烯（PE）",_xlfn.XLOOKUP(D16*E16/$N$3,基础数据!$O$51:$O$62,基础数据!$K$51:$K$62,"建议桥架敷设",1,1),$R$2="双壁波纹管",_xlfn.XLOOKUP(D16*E16/$N$3,基础数据!$O$67:$O$72,基础数据!$K$67:$K$72,"建议桥架敷设",1,1),$R$2="套接扣压式薄壁钢导管（KBG）",_xlfn.XLOOKUP(D16*E16/$N$3,基础数据!$O$106:$O$110,基础数据!$K$106:$K$110,"建议桥架敷设",1,1)) -> - | G16: =天诚!B19 -> UTP-CAT.6A | H16: =天诚!C19 -> 8.4 | I16: =(H16/2)^2*PI() -> 55.417694 | K16: =_xlfn.IFS(J16=0,"-",$R$2="低压流体输送用焊接钢管（SC）",_xlfn.XLOOKUP(I16*J16/$N$3,基础数据!$O$4:$O$15,基础数据!$K$4:$K$15,"建议桥架敷设",1,1),$R$2="套接紧定式钢管（JDG）",_xlfn.XLOOKUP(I16*J16/$N$3,基础数据!$O$16:$O$21,基础数据!$K$16:$K$21,"建议桥架敷设",1,1),$R$2="聚氯乙烯硬质电线管（PC）",_xlfn.XLOOKUP(I16*J16/$N$3,基础数据!$O$22:$O$27,基础数据!$K$22:$K$27,"建议桥架敷设",1,1),$R$2="聚氯乙烯半硬质电线管（FPC）",_xlfn.XLOOKUP(I16*J16/$N$3,基础数据!$O$28:$O$33,基础数据!$K$28:$K$33,"建议桥架敷设",1,1),$R$2="聚氯乙烯（PVC-U）",_xlfn.XLOOKUP(I16*J16/$N$3,基础数据!$O$37:$O$46,基础数据!$K$37:$K$46,"建议桥架敷设",1,1),$R$2="聚乙烯（PE）",_xlfn.XLOOKUP(I16*J16/$N$3,基础数据!$O$51:$O$62,基础数据!$K$51:$K$62,"建议桥架敷设",1,1),$R$2="双壁波纹管",_xlfn.XLOOKUP(I16*J16/$N$3,基础数据!$O$67:$O$72,基础数据!$K$67:$K$72,"建议桥架敷设",1,1),$R$2="套接扣压式薄壁钢导管（KBG）",_xlfn.XLOOKUP(I16*J16/$N$3,基础数据!$O$106:$O$110,基础数据!$K$106:$K$110,"建议桥架敷设",1,1)) -> - | L16: =飞鹤!A27 -> RVV-4*1.0 | M16: =飞鹤!B27 -> 9 | N16: =(M16/2)^2*PI() -> 63.617251 | P16: =_xlfn.IFS(O16=0,"-",$R$2="低压流体输送用焊接钢管（SC）",_xlfn.XLOOKUP(N16*O16/$N$3,基础数据!$O$4:$O$15,基础数据!$K$4:$K$15,"建议桥架敷设",1,1),$R$2="套接紧定式钢管（JDG）",_xlfn.XLOOKUP(N16*O16/$N$3,基础数据!$O$16:$O$21,基础数据!$K$16:$K$21,"建议桥架敷设",1,1),$R$2="聚氯乙烯硬质电线管（PC）",_xlfn.XLOOKUP(N16*O16/$N$3,基础数据!$O$22:$O$27,基础数据!$K$22:$K$27,"建议桥架敷设",1,1),$R$2="聚氯乙烯半硬质电线管（FPC）",_xlfn.XLOOKUP(N16*O16/$N$3,基础数据!$O$28:$O$33,基础数据!$K$28:$K$33,"建议桥架敷设",1,1),$R$2="聚氯乙烯（PVC-U）",_xlfn.XLOOKUP(N16*O16/$N$3,基础数据!$O$37:$O$46,基础数据!$K$37:$K$46,"建议桥架敷设",1,1),$R$2="聚乙烯（PE）",_xlfn.XLOOKUP(N16*O16/$N$3,基础数据!$O$51:$O$62,基础数据!$K$51:$K$62,"建议桥架敷设",1,1),$R$2="双壁波纹管",_xlfn.XLOOKUP(N16*O16/$N$3,基础数据!$O$67:$O$72,基础数据!$K$67:$K$72,"建议桥架敷设",1,1),$R$2="套接扣压式薄壁钢导管（KBG）",_xlfn.XLOOKUP(N16*O16/$N$3,基础数据!$O$106:$O$110,基础数据!$K$106:$K$110,"建议桥架敷设",1,1)) -> - | Q16: =飞鹤!A104 -> RVVP-4*1.0 | R16: =飞鹤!B104 -> 10.5 | S16: =(R16/2)^2*PI() -> 86.590148 | U16: =_xlfn.IFS(T16=0,"-",$R$2="低压流体输送用焊接钢管（SC）",_xlfn.XLOOKUP(S16*T16/$N$3,基础数据!$O$4:$O$15,基础数据!$K$4:$K$15,"建议桥架敷设",1,1),$R$2="套接紧定式钢管（JDG）",_xlfn.XLOOKUP(S16*T16/$N$3,基础数据!$O$16:$O$21,基础数据!$K$16:$K$21,"建议桥架敷设",1,1),$R$2="聚氯乙烯硬质电线管（PC）",_xlfn.XLOOKUP(S16*T16/$N$3,基础数据!$O$22:$O$27,基础数据!$K$22:$K$27,"建议桥架敷设",1,1),$R$2="聚氯乙烯半硬质电线管（FPC）",_xlfn.XLOOKUP(S16*T16/$N$3,基础数据!$O$28:$O$33,基础数据!$K$28:$K$33,"建议桥架敷设",1,1),$R$2="聚氯乙烯（PVC-U）",_xlfn.XLOOKUP(S16*T16/$N$3,基础数据!$O$37:$O$46,基础数据!$K$37:$K$46,"建议桥架敷设",1,1),$R$2="聚乙烯（PE）",_xlfn.XLOOKUP(S16*T16/$N$3,基础数据!$O$51:$O$62,基础数据!$K$51:$K$62,"建议桥架敷设",1,1),$R$2="双壁波纹管",_xlfn.XLOOKUP(S16*T16/$N$3,基础数据!$O$67:$O$72,基础数据!$K$67:$K$72,"建议桥架敷设",1,1),$R$2="套接扣压式薄壁钢导管（KBG）",_xlfn.XLOOKUP(S16*T16/$N$3,基础数据!$O$106:$O$110,基础数据!$K$106:$K$110,"建议桥架敷设",1,1)) -> - | V16: 音响线 | W16: 外径 | X16: 截面积 | Y16: 根数 | Z16: 建议管径
B17: =长飞!A10 -> 48芯室内光缆 | C17: =长飞!B10 -> 14.8 | D17: =(C17/2)^2*PI() -> 172.03361 | F17: =_xlfn.IFS(E17=0,"-",E17=1,_xlfn.IFS($R$2="低压流体输送用焊接钢管（SC）",_xlfn.XLOOKUP(C17/$N$2,基础数据!$N$4:$N$15,基础数据!$K$4:$K$15,"建议桥架敷设",1,1),$R$2="套接紧定式钢管（JDG）",_xlfn.XLOOKUP(C17/$N$2,基础数据!$N$16:$N$21,基础数据!$K$16:$K$21,"建议桥架敷设",1,1),$R$2="聚氯乙烯硬质电线管（PC）",_xlfn.XLOOKUP(C17/$N$2,基础数据!$N$22:$N$27,基础数据!$K$22:$K$27,"建议桥架敷设",1,1),$R$2="聚氯乙烯半硬质电线管（FPC）",_xlfn.XLOOKUP(C17/$N$2,基础数据!$N$28:$N$33,基础数据!$K$28:$K$33,"建议桥架敷设",1,1),$R$2="聚氯乙烯（PVC-U）",_xlfn.XLOOKUP(C17/$N$2,基础数据!$N$37:$N$46,基础数据!$K$37:$K$46,"建议桥架敷设",1,1),$R$2="聚乙烯（PE）",_xlfn.XLOOKUP(C17/$N$2,基础数据!$N$51:$N$62,基础数据!$K$51:$K$62,"建议桥架敷设",1,1),$R$2="双壁波纹管",_xlfn.XLOOKUP(C17/$N$2,基础数据!$N$67:$N$72,基础数据!$K$67:$K$72,"建议桥架敷设",1,1),$R$2="套接扣压式薄壁钢导管（KBG）",_xlfn.XLOOKUP(C17/$N$2,基础数据!$N$106:$N$110,基础数据!$K$106:$K$110,"建议桥架敷设",1,1)),$R$2="低压流体输送用焊接钢管（SC）",_xlfn.XLOOKUP(D17*E17/$N$3,基础数据!$O$4:$O$15,基础数据!$K$4:$K$15,"建议桥架敷设",1,1),$R$2="套接紧定式钢管（JDG）",_xlfn.XLOOKUP(D17*E17/$N$3,基础数据!$O$16:$O$21,基础数据!$K$16:$K$21,"建议桥架敷设",1,1),$R$2="聚氯乙烯硬质电线管（PC）",_xlfn.XLOOKUP(D17*E17/$N$3,基础数据!$O$22:$O$27,基础数据!$K$22:$K$27,"建议桥架敷设",1,1),$R$2="聚氯乙烯半硬质电线管（FPC）",_xlfn.XLOOKUP(D17*E17/$N$3,基础数据!$O$28:$O$33,基础数据!$K$28:$K$33,"建议桥架敷设",1,1),$R$2="聚氯乙烯（PVC-U）",_xlfn.XLOOKUP(D17*E17/$N$3,基础数据!$O$37:$O$46,基础数据!$K$37:$K$46,"建议桥架敷设",1,1),$R$2="聚乙烯（PE）",_xlfn.XLOOKUP(D17*E17/$N$3,基础数据!$O$51:$O$62,基础数据!$K$51:$K$62,"建议桥架敷设",1,1),$R$2="双壁波纹管",_xlfn.XLOOKUP(D17*E17/$N$3,基础数据!$O$67:$O$72,基础数据!$K$67:$K$72,"建议桥架敷设",1,1),$R$2="套接扣压式薄壁钢导管（KBG）",_xlfn.XLOOKUP(D17*E17/$N$3,基础数据!$O$106:$O$110,基础数据!$K$106:$K$110,"建议桥架敷设",1,1)) -> - | G17: =天诚!B20 -> FTP-CAT.6A | H17: =天诚!C20 -> 7.3 | I17: =(H17/2)^2*PI() -> 41.853868 | K17: =_xlfn.IFS(J17=0,"-",$R$2="低压流体输送用焊接钢管（SC）",_xlfn.XLOOKUP(I17*J17/$N$3,基础数据!$O$4:$O$15,基础数据!$K$4:$K$15,"建议桥架敷设",1,1),$R$2="套接紧定式钢管（JDG）",_xlfn.XLOOKUP(I17*J17/$N$3,基础数据!$O$16:$O$21,基础数据!$K$16:$K$21,"建议桥架敷设",1,1),$R$2="聚氯乙烯硬质电线管（PC）",_xlfn.XLOOKUP(I17*J17/$N$3,基础数据!$O$22:$O$27,基础数据!$K$22:$K$27,"建议桥架敷设",1,1),$R$2="聚氯乙烯半硬质电线管（FPC）",_xlfn.XLOOKUP(I17*J17/$N$3,基础数据!$O$28:$O$33,基础数据!$K$28:$K$33,"建议桥架敷设",1,1),$R$2="聚氯乙烯（PVC-U）",_xlfn.XLOOKUP(I17*J17/$N$3,基础数据!$O$37:$O$46,基础数据!$K$37:$K$46,"建议桥架敷设",1,1),$R$2="聚乙烯（PE）",_xlfn.XLOOKUP(I17*J17/$N$3,基础数据!$O$51:$O$62,基础数据!$K$51:$K$62,"建议桥架敷设",1,1),$R$2="双壁波纹管",_xlfn.XLOOKUP(I17*J17/$N$3,基础数据!$O$67:$O$72,基础数据!$K$67:$K$72,"建议桥架敷设",1,1),$R$2="套接扣压式薄壁钢导管（KBG）",_xlfn.XLOOKUP(I17*J17/$N$3,基础数据!$O$106:$O$110,基础数据!$K$106:$K$110,"建议桥架敷设",1,1)) -> - | L17: =飞鹤!A28 -> RVV-4*1.5 | M17: =飞鹤!B28 -> 10.5 | N17: =(M17/2)^2*PI() -> 86.590148 | P17: =_xlfn.IFS(O17=0,"-",$R$2="低压流体输送用焊接钢管（SC）",_xlfn.XLOOKUP(N17*O17/$N$3,基础数据!$O$4:$O$15,基础数据!$K$4:$K$15,"建议桥架敷设",1,1),$R$2="套接紧定式钢管（JDG）",_xlfn.XLOOKUP(N17*O17/$N$3,基础数据!$O$16:$O$21,基础数据!$K$16:$K$21,"建议桥架敷设",1,1),$R$2="聚氯乙烯硬质电线管（PC）",_xlfn.XLOOKUP(N17*O17/$N$3,基础数据!$O$22:$O$27,基础数据!$K$22:$K$27,"建议桥架敷设",1,1),$R$2="聚氯乙烯半硬质电线管（FPC）",_xlfn.XLOOKUP(N17*O17/$N$3,基础数据!$O$28:$O$33,基础数据!$K$28:$K$33,"建议桥架敷设",1,1),$R$2="聚氯乙烯（PVC-U）",_xlfn.XLOOKUP(N17*O17/$N$3,基础数据!$O$37:$O$46,基础数据!$K$37:$K$46,"建议桥架敷设",1,1),$R$2="聚乙烯（PE）",_xlfn.XLOOKUP(N17*O17/$N$3,基础数据!$O$51:$O$62,基础数据!$K$51:$K$62,"建议桥架敷设",1,1),$R$2="双壁波纹管",_xlfn.XLOOKUP(N17*O17/$N$3,基础数据!$O$67:$O$72,基础数据!$K$67:$K$72,"建议桥架敷设",1,1),$R$2="套接扣压式薄壁钢导管（KBG）",_xlfn.XLOOKUP(N17*O17/$N$3,基础数据!$O$106:$O$110,基础数据!$K$106:$K$110,"建议桥架敷设",1,1)) -> - | Q17: =飞鹤!A105 -> RVVP-4*1.5 | R17: =飞鹤!B105 -> 11.5 | S17: =(R17/2)^2*PI() -> 103.86891 | U17: =_xlfn.IFS(T17=0,"-",$R$2="低压流体输送用焊接钢管（SC）",_xlfn.XLOOKUP(S17*T17/$N$3,基础数据!$O$4:$O$15,基础数据!$K$4:$K$15,"建议桥架敷设",1,1),$R$2="套接紧定式钢管（JDG）",_xlfn.XLOOKUP(S17*T17/$N$3,基础数据!$O$16:$O$21,基础数据!$K$16:$K$21,"建议桥架敷设",1,1),$R$2="聚氯乙烯硬质电线管（PC）",_xlfn.XLOOKUP(S17*T17/$N$3,基础数据!$O$22:$O$27,基础数据!$K$22:$K$27,"建议桥架敷设",1,1),$R$2="聚氯乙烯半硬质电线管（FPC）",_xlfn.XLOOKUP(S17*T17/$N$3,基础数据!$O$28:$O$33,基础数据!$K$28:$K$33,"建议桥架敷设",1,1),$R$2="聚氯乙烯（PVC-U）",_xlfn.XLOOKUP(S17*T17/$N$3,基础数据!$O$37:$O$46,基础数据!$K$37:$K$46,"建议桥架敷设",1,1),$R$2="聚乙烯（PE）",_xlfn.XLOOKUP(S17*T17/$N$3,基础数据!$O$51:$O$62,基础数据!$K$51:$K$62,"建议桥架敷设",1,1),$R$2="双壁波纹管",_xlfn.XLOOKUP(S17*T17/$N$3,基础数据!$O$67:$O$72,基础数据!$K$67:$K$72,"建议桥架敷设",1,1),$R$2="套接扣压式薄壁钢导管（KBG）",_xlfn.XLOOKUP(S17*T17/$N$3,基础数据!$O$106:$O$110,基础数据!$K$106:$K$110,"建议桥架敷设",1,1)) -> - | V17: =天诚!B49 -> GYX-2*1.0 | W17: =天诚!C49 -> 8.4 | X17: =(W17/2)^2*PI() -> 55.417694 | Z17: =_xlfn.IFS(Y17=0,"-",$R$2="低压流体输送用焊接钢管（SC）",_xlfn.XLOOKUP(X17*Y17/$N$3,基础数据!$O$4:$O$15,基础数据!$K$4:$K$15,"建议桥架敷设",1,1),$R$2="套接紧定式钢管（JDG）",_xlfn.XLOOKUP(X17*Y17/$N$3,基础数据!$O$16:$O$21,基础数据!$K$16:$K$21,"建议桥架敷设",1,1),$R$2="聚氯乙烯硬质电线管（PC）",_xlfn.XLOOKUP(X17*Y17/$N$3,基础数据!$O$22:$O$27,基础数据!$K$22:$K$27,"建议桥架敷设",1,1),$R$2="聚氯乙烯半硬质电线管（FPC）",_xlfn.XLOOKUP(X17*Y17/$N$3,基础数据!$O$28:$O$33,基础数据!$K$28:$K$33,"建议桥架敷设",1,1),$R$2="聚氯乙烯（PVC-U）",_xlfn.XLOOKUP(X17*Y17/$N$3,基础数据!$O$37:$O$46,基础数据!$K$37:$K$46,"建议桥架敷设",1,1),$R$2="聚乙烯（PE）",_xlfn.XLOOKUP(X17*Y17/$N$3,基础数据!$O$51:$O$62,基础数据!$K$51:$K$62,"建议桥架敷设",1,1),$R$2="双壁波纹管",_xlfn.XLOOKUP(X17*Y17/$N$3,基础数据!$O$67:$O$72,基础数据!$K$67:$K$72,"建议桥架敷设",1,1),$R$2="套接扣压式薄壁钢导管（KBG）",_xlfn.XLOOKUP(X17*Y17/$N$3,基础数据!$O$106:$O$110,基础数据!$K$106:$K$110,"建议桥架敷设",1,1)) -> -
B18: =长飞!A11 -> 72芯室内光缆 | C18: =长飞!B11 -> 17.5 | D18: =(C18/2)^2*PI() -> 240.52819 | F18: =_xlfn.IFS(E18=0,"-",E18=1,_xlfn.IFS($R$2="低压流体输送用焊接钢管（SC）",_xlfn.XLOOKUP(C18/$N$2,基础数据!$N$4:$N$15,基础数据!$K$4:$K$15,"建议桥架敷设",1,1),$R$2="套接紧定式钢管（JDG）",_xlfn.XLOOKUP(C18/$N$2,基础数据!$N$16:$N$21,基础数据!$K$16:$K$21,"建议桥架敷设",1,1),$R$2="聚氯乙烯硬质电线管（PC）",_xlfn.XLOOKUP(C18/$N$2,基础数据!$N$22:$N$27,基础数据!$K$22:$K$27,"建议桥架敷设",1,1),$R$2="聚氯乙烯半硬质电线管（FPC）",_xlfn.XLOOKUP(C18/$N$2,基础数据!$N$28:$N$33,基础数据!$K$28:$K$33,"建议桥架敷设",1,1),$R$2="聚氯乙烯（PVC-U）",_xlfn.XLOOKUP(C18/$N$2,基础数据!$N$37:$N$46,基础数据!$K$37:$K$46,"建议桥架敷设",1,1),$R$2="聚乙烯（PE）",_xlfn.XLOOKUP(C18/$N$2,基础数据!$N$51:$N$62,基础数据!$K$51:$K$62,"建议桥架敷设",1,1),$R$2="双壁波纹管",_xlfn.XLOOKUP(C18/$N$2,基础数据!$N$67:$N$72,基础数据!$K$67:$K$72,"建议桥架敷设",1,1),$R$2="套接扣压式薄壁钢导管（KBG）",_xlfn.XLOOKUP(C18/$N$2,基础数据!$N$106:$N$110,基础数据!$K$106:$K$110,"建议桥架敷设",1,1)),$R$2="低压流体输送用焊接钢管（SC）",_xlfn.XLOOKUP(D18*E18/$N$3,基础数据!$O$4:$O$15,基础数据!$K$4:$K$15,"建议桥架敷设",1,1),$R$2="套接紧定式钢管（JDG）",_xlfn.XLOOKUP(D18*E18/$N$3,基础数据!$O$16:$O$21,基础数据!$K$16:$K$21,"建议桥架敷设",1,1),$R$2="聚氯乙烯硬质电线管（PC）",_xlfn.XLOOKUP(D18*E18/$N$3,基础数据!$O$22:$O$27,基础数据!$K$22:$K$27,"建议桥架敷设",1,1),$R$2="聚氯乙烯半硬质电线管（FPC）",_xlfn.XLOOKUP(D18*E18/$N$3,基础数据!$O$28:$O$33,基础数据!$K$28:$K$33,"建议桥架敷设",1,1),$R$2="聚氯乙烯（PVC-U）",_xlfn.XLOOKUP(D18*E18/$N$3,基础数据!$O$37:$O$46,基础数据!$K$37:$K$46,"建议桥架敷设",1,1),$R$2="聚乙烯（PE）",_xlfn.XLOOKUP(D18*E18/$N$3,基础数据!$O$51:$O$62,基础数据!$K$51:$K$62,"建议桥架敷设",1,1),$R$2="双壁波纹管",_xlfn.XLOOKUP(D18*E18/$N$3,基础数据!$O$67:$O$72,基础数据!$K$67:$K$72,"建议桥架敷设",1,1),$R$2="套接扣压式薄壁钢导管（KBG）",_xlfn.XLOOKUP(D18*E18/$N$3,基础数据!$O$106:$O$110,基础数据!$K$106:$K$110,"建议桥架敷设",1,1)) -> - | G18: =天诚!B22 -> U/FTP-CAT.6A | H18: =天诚!C22 -> 7.5 | I18: =(H18/2)^2*PI() -> 44.178647 | K18: =_xlfn.IFS(J18=0,"-",$R$2="低压流体输送用焊接钢管（SC）",_xlfn.XLOOKUP(I18*J18/$N$3,基础数据!$O$4:$O$15,基础数据!$K$4:$K$15,"建议桥架敷设",1,1),$R$2="套接紧定式钢管（JDG）",_xlfn.XLOOKUP(I18*J18/$N$3,基础数据!$O$16:$O$21,基础数据!$K$16:$K$21,"建议桥架敷设",1,1),$R$2="聚氯乙烯硬质电线管（PC）",_xlfn.XLOOKUP(I18*J18/$N$3,基础数据!$O$22:$O$27,基础数据!$K$22:$K$27,"建议桥架敷设",1,1),$R$2="聚氯乙烯半硬质电线管（FPC）",_xlfn.XLOOKUP(I18*J18/$N$3,基础数据!$O$28:$O$33,基础数据!$K$28:$K$33,"建议桥架敷设",1,1),$R$2="聚氯乙烯（PVC-U）",_xlfn.XLOOKUP(I18*J18/$N$3,基础数据!$O$37:$O$46,基础数据!$K$37:$K$46,"建议桥架敷设",1,1),$R$2="聚乙烯（PE）",_xlfn.XLOOKUP(I18*J18/$N$3,基础数据!$O$51:$O$62,基础数据!$K$51:$K$62,"建议桥架敷设",1,1),$R$2="双壁波纹管",_xlfn.XLOOKUP(I18*J18/$N$3,基础数据!$O$67:$O$72,基础数据!$K$67:$K$72,"建议桥架敷设",1,1),$R$2="套接扣压式薄壁钢导管（KBG）",_xlfn.XLOOKUP(I18*J18/$N$3,基础数据!$O$106:$O$110,基础数据!$K$106:$K$110,"建议桥架敷设",1,1)) -> - | L18: =飞鹤!A29 -> RVV-4*2.5 | M18: =飞鹤!B29 -> 12.5 | N18: =(M18/2)^2*PI() -> 122.71846 | P18: =_xlfn.IFS(O18=0,"-",$R$2="低压流体输送用焊接钢管（SC）",_xlfn.XLOOKUP(N18*O18/$N$3,基础数据!$O$4:$O$15,基础数据!$K$4:$K$15,"建议桥架敷设",1,1),$R$2="套接紧定式钢管（JDG）",_xlfn.XLOOKUP(N18*O18/$N$3,基础数据!$O$16:$O$21,基础数据!$K$16:$K$21,"建议桥架敷设",1,1),$R$2="聚氯乙烯硬质电线管（PC）",_xlfn.XLOOKUP(N18*O18/$N$3,基础数据!$O$22:$O$27,基础数据!$K$22:$K$27,"建议桥架敷设",1,1),$R$2="聚氯乙烯半硬质电线管（FPC）",_xlfn.XLOOKUP(N18*O18/$N$3,基础数据!$O$28:$O$33,基础数据!$K$28:$K$33,"建议桥架敷设",1,1),$R$2="聚氯乙烯（PVC-U）",_xlfn.XLOOKUP(N18*O18/$N$3,基础数据!$O$37:$O$46,基础数据!$K$37:$K$46,"建议桥架敷设",1,1),$R$2="聚乙烯（PE）",_xlfn.XLOOKUP(N18*O18/$N$3,基础数据!$O$51:$O$62,基础数据!$K$51:$K$62,"建议桥架敷设",1,1),$R$2="双壁波纹管",_xlfn.XLOOKUP(N18*O18/$N$3,基础数据!$O$67:$O$72,基础数据!$K$67:$K$72,"建议桥架敷设",1,1),$R$2="套接扣压式薄壁钢导管（KBG）",_xlfn.XLOOKUP(N18*O18/$N$3,基础数据!$O$106:$O$110,基础数据!$K$106:$K$110,"建议桥架敷设",1,1)) -> - | Q18: =飞鹤!A106 -> RVVP-4*2.5 | R18: =飞鹤!B106 -> 13.6 | S18: =(R18/2)^2*PI() -> 145.26724 | U18: =_xlfn.IFS(T18=0,"-",$R$2="低压流体输送用焊接钢管（SC）",_xlfn.XLOOKUP(S18*T18/$N$3,基础数据!$O$4:$O$15,基础数据!$K$4:$K$15,"建议桥架敷设",1,1),$R$2="套接紧定式钢管（JDG）",_xlfn.XLOOKUP(S18*T18/$N$3,基础数据!$O$16:$O$21,基础数据!$K$16:$K$21,"建议桥架敷设",1,1),$R$2="聚氯乙烯硬质电线管（PC）",_xlfn.XLOOKUP(S18*T18/$N$3,基础数据!$O$22:$O$27,基础数据!$K$22:$K$27,"建议桥架敷设",1,1),$R$2="聚氯乙烯半硬质电线管（FPC）",_xlfn.XLOOKUP(S18*T18/$N$3,基础数据!$O$28:$O$33,基础数据!$K$28:$K$33,"建议桥架敷设",1,1),$R$2="聚氯乙烯（PVC-U）",_xlfn.XLOOKUP(S18*T18/$N$3,基础数据!$O$37:$O$46,基础数据!$K$37:$K$46,"建议桥架敷设",1,1),$R$2="聚乙烯（PE）",_xlfn.XLOOKUP(S18*T18/$N$3,基础数据!$O$51:$O$62,基础数据!$K$51:$K$62,"建议桥架敷设",1,1),$R$2="双壁波纹管",_xlfn.XLOOKUP(S18*T18/$N$3,基础数据!$O$67:$O$72,基础数据!$K$67:$K$72,"建议桥架敷设",1,1),$R$2="套接扣压式薄壁钢导管（KBG）",_xlfn.XLOOKUP(S18*T18/$N$3,基础数据!$O$106:$O$110,基础数据!$K$106:$K$110,"建议桥架敷设",1,1)) -> - | V18: =天诚!B50 -> GYX-2*1.5 | W18: =天诚!C50 -> 8.72 | X18: =(W18/2)^2*PI() -> 59.72042 | Z18: =_xlfn.IFS(Y18=0,"-",$R$2="低压流体输送用焊接钢管（SC）",_xlfn.XLOOKUP(X18*Y18/$N$3,基础数据!$O$4:$O$15,基础数据!$K$4:$K$15,"建议桥架敷设",1,1),$R$2="套接紧定式钢管（JDG）",_xlfn.XLOOKUP(X18*Y18/$N$3,基础数据!$O$16:$O$21,基础数据!$K$16:$K$21,"建议桥架敷设",1,1),$R$2="聚氯乙烯硬质电线管（PC）",_xlfn.XLOOKUP(X18*Y18/$N$3,基础数据!$O$22:$O$27,基础数据!$K$22:$K$27,"建议桥架敷设",1,1),$R$2="聚氯乙烯半硬质电线管（FPC）",_xlfn.XLOOKUP(X18*Y18/$N$3,基础数据!$O$28:$O$33,基础数据!$K$28:$K$33,"建议桥架敷设",1,1),$R$2="聚氯乙烯（PVC-U）",_xlfn.XLOOKUP(X18*Y18/$N$3,基础数据!$O$37:$O$46,基础数据!$K$37:$K$46,"建议桥架敷设",1,1),$R$2="聚乙烯（PE）",_xlfn.XLOOKUP(X18*Y18/$N$3,基础数据!$O$51:$O$62,基础数据!$K$51:$K$62,"建议桥架敷设",1,1),$R$2="双壁波纹管",_xlfn.XLOOKUP(X18*Y18/$N$3,基础数据!$O$67:$O$72,基础数据!$K$67:$K$72,"建议桥架敷设",1,1),$R$2="套接扣压式薄壁钢导管（KBG）",_xlfn.XLOOKUP(X18*Y18/$N$3,基础数据!$O$106:$O$110,基础数据!$K$106:$K$110,"建议桥架敷设",1,1)) -> -
B19: =长飞!A12 -> 96芯室内光缆 | C19: =长飞!B12 -> 20.7 | D19: =(C19/2)^2*PI() -> 336.53526 | F19: =_xlfn.IFS(E19=0,"-",E19=1,_xlfn.IFS($R$2="低压流体输送用焊接钢管（SC）",_xlfn.XLOOKUP(C19/$N$2,基础数据!$N$4:$N$15,基础数据!$K$4:$K$15,"建议桥架敷设",1,1),$R$2="套接紧定式钢管（JDG）",_xlfn.XLOOKUP(C19/$N$2,基础数据!$N$16:$N$21,基础数据!$K$16:$K$21,"建议桥架敷设",1,1),$R$2="聚氯乙烯硬质电线管（PC）",_xlfn.XLOOKUP(C19/$N$2,基础数据!$N$22:$N$27,基础数据!$K$22:$K$27,"建议桥架敷设",1,1),$R$2="聚氯乙烯半硬质电线管（FPC）",_xlfn.XLOOKUP(C19/$N$2,基础数据!$N$28:$N$33,基础数据!$K$28:$K$33,"建议桥架敷设",1,1),$R$2="聚氯乙烯（PVC-U）",_xlfn.XLOOKUP(C19/$N$2,基础数据!$N$37:$N$46,基础数据!$K$37:$K$46,"建议桥架敷设",1,1),$R$2="聚乙烯（PE）",_xlfn.XLOOKUP(C19/$N$2,基础数据!$N$51:$N$62,基础数据!$K$51:$K$62,"建议桥架敷设",1,1),$R$2="双壁波纹管",_xlfn.XLOOKUP(C19/$N$2,基础数据!$N$67:$N$72,基础数据!$K$67:$K$72,"建议桥架敷设",1,1),$R$2="套接扣压式薄壁钢导管（KBG）",_xlfn.XLOOKUP(C19/$N$2,基础数据!$N$106:$N$110,基础数据!$K$106:$K$110,"建议桥架敷设",1,1)),$R$2="低压流体输送用焊接钢管（SC）",_xlfn.XLOOKUP(D19*E19/$N$3,基础数据!$O$4:$O$15,基础数据!$K$4:$K$15,"建议桥架敷设",1,1),$R$2="套接紧定式钢管（JDG）",_xlfn.XLOOKUP(D19*E19/$N$3,基础数据!$O$16:$O$21,基础数据!$K$16:$K$21,"建议桥架敷设",1,1),$R$2="聚氯乙烯硬质电线管（PC）",_xlfn.XLOOKUP(D19*E19/$N$3,基础数据!$O$22:$O$27,基础数据!$K$22:$K$27,"建议桥架敷设",1,1),$R$2="聚氯乙烯半硬质电线管（FPC）",_xlfn.XLOOKUP(D19*E19/$N$3,基础数据!$O$28:$O$33,基础数据!$K$28:$K$33,"建议桥架敷设",1,1),$R$2="聚氯乙烯（PVC-U）",_xlfn.XLOOKUP(D19*E19/$N$3,基础数据!$O$37:$O$46,基础数据!$K$37:$K$46,"建议桥架敷设",1,1),$R$2="聚乙烯（PE）",_xlfn.XLOOKUP(D19*E19/$N$3,基础数据!$O$51:$O$62,基础数据!$K$51:$K$62,"建议桥架敷设",1,1),$R$2="双壁波纹管",_xlfn.XLOOKUP(D19*E19/$N$3,基础数据!$O$67:$O$72,基础数据!$K$67:$K$72,"建议桥架敷设",1,1),$R$2="套接扣压式薄壁钢导管（KBG）",_xlfn.XLOOKUP(D19*E19/$N$3,基础数据!$O$106:$O$110,基础数据!$K$106:$K$110,"建议桥架敷设",1,1)) -> - | G19: =天诚!B23 -> SFTP-CAT.6A | H19: =天诚!C23 -> 8.2 | I19: =(H19/2)^2*PI() -> 52.810173 | K19: =_xlfn.IFS(J19=0,"-",$R$2="低压流体输送用焊接钢管（SC）",_xlfn.XLOOKUP(I19*J19/$N$3,基础数据!$O$4:$O$15,基础数据!$K$4:$K$15,"建议桥架敷设",1,1),$R$2="套接紧定式钢管（JDG）",_xlfn.XLOOKUP(I19*J19/$N$3,基础数据!$O$16:$O$21,基础数据!$K$16:$K$21,"建议桥架敷设",1,1),$R$2="聚氯乙烯硬质电线管（PC）",_xlfn.XLOOKUP(I19*J19/$N$3,基础数据!$O$22:$O$27,基础数据!$K$22:$K$27,"建议桥架敷设",1,1),$R$2="聚氯乙烯半硬质电线管（FPC）",_xlfn.XLOOKUP(I19*J19/$N$3,基础数据!$O$28:$O$33,基础数据!$K$28:$K$33,"建议桥架敷设",1,1),$R$2="聚氯乙烯（PVC-U）",_xlfn.XLOOKUP(I19*J19/$N$3,基础数据!$O$37:$O$46,基础数据!$K$37:$K$46,"建议桥架敷设",1,1),$R$2="聚乙烯（PE）",_xlfn.XLOOKUP(I19*J19/$N$3,基础数据!$O$51:$O$62,基础数据!$K$51:$K$62,"建议桥架敷设",1,1),$R$2="双壁波纹管",_xlfn.XLOOKUP(I19*J19/$N$3,基础数据!$O$67:$O$72,基础数据!$K$67:$K$72,"建议桥架敷设",1,1),$R$2="套接扣压式薄壁钢导管（KBG）",_xlfn.XLOOKUP(I19*J19/$N$3,基础数据!$O$106:$O$110,基础数据!$K$106:$K$110,"建议桥架敷设",1,1)) -> - | N19: =(M19/2)^2*PI() -> 0 | P19: =_xlfn.IFS(O19=0,"-",$R$2="低压流体输送用焊接钢管（SC）",_xlfn.XLOOKUP(N19*O19/$N$3,基础数据!$O$4:$O$15,基础数据!$K$4:$K$15,"建议桥架敷设",1,1),$R$2="套接紧定式钢管（JDG）",_xlfn.XLOOKUP(N19*O19/$N$3,基础数据!$O$16:$O$21,基础数据!$K$16:$K$21,"建议桥架敷设",1,1),$R$2="聚氯乙烯硬质电线管（PC）",_xlfn.XLOOKUP(N19*O19/$N$3,基础数据!$O$22:$O$27,基础数据!$K$22:$K$27,"建议桥架敷设",1,1),$R$2="聚氯乙烯半硬质电线管（FPC）",_xlfn.XLOOKUP(N19*O19/$N$3,基础数据!$O$28:$O$33,基础数据!$K$28:$K$33,"建议桥架敷设",1,1),$R$2="聚氯乙烯（PVC-U）",_xlfn.XLOOKUP(N19*O19/$N$3,基础数据!$O$37:$O$46,基础数据!$K$37:$K$46,"建议桥架敷设",1,1),$R$2="聚乙烯（PE）",_xlfn.XLOOKUP(N19*O19/$N$3,基础数据!$O$51:$O$62,基础数据!$K$51:$K$62,"建议桥架敷设",1,1),$R$2="双壁波纹管",_xlfn.XLOOKUP(N19*O19/$N$3,基础数据!$O$67:$O$72,基础数据!$K$67:$K$72,"建议桥架敷设",1,1),$R$2="套接扣压式薄壁钢导管（KBG）",_xlfn.XLOOKUP(N19*O19/$N$3,基础数据!$O$106:$O$110,基础数据!$K$106:$K$110,"建议桥架敷设",1,1)) -> - | Q19: =飞鹤!A116 -> RVVP-6*0.5 | R19: =飞鹤!B116 -> 10.2 | S19: =(R19/2)^2*PI() -> 81.712825 | U19: =_xlfn.IFS(T19=0,"-",$R$2="低压流体输送用焊接钢管（SC）",_xlfn.XLOOKUP(S19*T19/$N$3,基础数据!$O$4:$O$15,基础数据!$K$4:$K$15,"建议桥架敷设",1,1),$R$2="套接紧定式钢管（JDG）",_xlfn.XLOOKUP(S19*T19/$N$3,基础数据!$O$16:$O$21,基础数据!$K$16:$K$21,"建议桥架敷设",1,1),$R$2="聚氯乙烯硬质电线管（PC）",_xlfn.XLOOKUP(S19*T19/$N$3,基础数据!$O$22:$O$27,基础数据!$K$22:$K$27,"建议桥架敷设",1,1),$R$2="聚氯乙烯半硬质电线管（FPC）",_xlfn.XLOOKUP(S19*T19/$N$3,基础数据!$O$28:$O$33,基础数据!$K$28:$K$33,"建议桥架敷设",1,1),$R$2="聚氯乙烯（PVC-U）",_xlfn.XLOOKUP(S19*T19/$N$3,基础数据!$O$37:$O$46,基础数据!$K$37:$K$46,"建议桥架敷设",1,1),$R$2="聚乙烯（PE）",_xlfn.XLOOKUP(S19*T19/$N$3,基础数据!$O$51:$O$62,基础数据!$K$51:$K$62,"建议桥架敷设",1,1),$R$2="双壁波纹管",_xlfn.XLOOKUP(S19*T19/$N$3,基础数据!$O$67:$O$72,基础数据!$K$67:$K$72,"建议桥架敷设",1,1),$R$2="套接扣压式薄壁钢导管（KBG）",_xlfn.XLOOKUP(S19*T19/$N$3,基础数据!$O$106:$O$110,基础数据!$K$106:$K$110,"建议桥架敷设",1,1)) -> - | V19: =天诚!B51 -> GYX-2*2.0 | W19: =天诚!C51 -> 9.14 | X19: =(W19/2)^2*PI() -> 65.611848 | Z19: =_xlfn.IFS(Y19=0,"-",$R$2="低压流体输送用焊接钢管（SC）",_xlfn.XLOOKUP(X19*Y19/$N$3,基础数据!$O$4:$O$15,基础数据!$K$4:$K$15,"建议桥架敷设",1,1),$R$2="套接紧定式钢管（JDG）",_xlfn.XLOOKUP(X19*Y19/$N$3,基础数据!$O$16:$O$21,基础数据!$K$16:$K$21,"建议桥架敷设",1,1),$R$2="聚氯乙烯硬质电线管（PC）",_xlfn.XLOOKUP(X19*Y19/$N$3,基础数据!$O$22:$O$27,基础数据!$K$22:$K$27,"建议桥架敷设",1,1),$R$2="聚氯乙烯半硬质电线管（FPC）",_xlfn.XLOOKUP(X19*Y19/$N$3,基础数据!$O$28:$O$33,基础数据!$K$28:$K$33,"建议桥架敷设",1,1),$R$2="聚氯乙烯（PVC-U）",_xlfn.XLOOKUP(X19*Y19/$N$3,基础数据!$O$37:$O$46,基础数据!$K$37:$K$46,"建议桥架敷设",1,1),$R$2="聚乙烯（PE）",_xlfn.XLOOKUP(X19*Y19/$N$3,基础数据!$O$51:$O$62,基础数据!$K$51:$K$62,"建议桥架敷设",1,1),$R$2="双壁波纹管",_xlfn.XLOOKUP(X19*Y19/$N$3,基础数据!$O$67:$O$72,基础数据!$K$67:$K$72,"建议桥架敷设",1,1),$R$2="套接扣压式薄壁钢导管（KBG）",_xlfn.XLOOKUP(X19*Y19/$N$3,基础数据!$O$106:$O$110,基础数据!$K$106:$K$110,"建议桥架敷设",1,1)) -> -
